Workbook

Sheet TỔNG KLH + TN
A1: https://docs.google.com/spreadsheets/d/1i-eBGlD9GCKjjW_oVzhKXTG7rkg5adA55PmkVD7FH2A/edit?usp=sharing
A2: =IFERROR(__xludf.DUMMYFUNCTION("IMPORTRANGE(A1,""TỔNG!A1:L"")"),"mã mmtb") -> mã mmtb | B2: =IFERROR(__xludf.DUMMYFUNCTION("""COMPUTED_VALUE"""),"tên mmtb") -> tên mmtb | C2: =IFERROR(__xludf.DUMMYFUNCTION("""COMPUTED_VALUE"""),"đvsd") -> đvsd | D2: =IFERROR(__xludf.DUMMYFUNCTION("""COMPUTED_VALUE"""),"NHÃN HIỆU") -> NHÃN HIỆU | E2: =IFERROR(__xludf.DUMMYFUNCTION("""COMPUTED_VALUE"""),"XUẤT XỨ") -> XUẤT XỨ | F2: =IFERROR(__xludf.DUMMYFUNCTION("""COMPUTED_VALUE"""),"NĂM SX") -> NĂM SX | G2: =IFERROR(__xludf.DUMMYFUNCTION("""COMPUTED_VALUE"""),"MODEL") -> MODEL | H2: =IFERROR(__xludf.DUMMYFUNCTION("""COMPUTED_VALUE"""),"CÔNG SUẤT") -> CÔNG SUẤT | I2: =IFERROR(__xludf.DUMMYFUNCTION("""COMPUTED_VALUE"""),"Số khung") -> Số khung | J2: =IFERROR(__xludf.DUMMYFUNCTION("""COMPUTED_VALUE"""),"Số máy") -> Số máy | K2: =IFERROR(__xludf.DUMMYFUNCTION("""COMPUTED_VALUE"""),"Định mức nhiên liệu (l/h) hoặc (l/km)") -> Định mức nhiên liệu (l/h) hoặc (l/km) | L2: =IFERROR(__xludf.DUMMYFUNCTION("""COMPUTED_VALUE"""),"Tình trạng hợp đồng") -> Tình trạng hợp đồng
A3: =IFERROR(__xludf.DUMMYFUNCTION("""COMPUTED_VALUE"""),1) -> 1 | B3: =IFERROR(__xludf.DUMMYFUNCTION("""COMPUTED_VALUE"""),2) -> 2 | C3: =IFERROR(__xludf.DUMMYFUNCTION("""COMPUTED_VALUE"""),3) -> 3 | D3: =IFERROR(__xludf.DUMMYFUNCTION("""COMPUTED_VALUE"""),4) -> 4 | E3: =IFERROR(__xludf.DUMMYFUNCTION("""COMPUTED_VALUE"""),5) -> 5 | F3: =IFERROR(__xludf.DUMMYFUNCTION("""COMPUTED_VALUE"""),6) -> 6 | G3: =IFERROR(__xludf.DUMMYFUNCTION("""COMPUTED_VALUE"""),7) -> 7 | H3: =IFERROR(__xludf.DUMMYFUNCTION("""COMPUTED_VALUE"""),8) -> 8 | I3: =IFERROR(__xludf.DUMMYFUNCTION("""COMPUTED_VALUE"""),9) -> 9 | J3: =IFERROR(__xludf.DUMMYFUNCTION("""COMPUTED_VALUE"""),10) -> 10 | K3: =IFERROR(__xludf.DUMMYFUNCTION("""COMPUTED_VALUE"""),11) -> 11 | L3: =IFERROR(__xludf.DUMMYFUNCTION("""COMPUTED_VALUE"""),12) -> 12
A4: =IFERROR(__xludf.DUMMYFUNCTION("""COMPUTED_VALUE"""),"CHT-MĐA-001") -> CHT-MĐA-001 | B4: =IFERROR(__xludf.DUMMYFUNCTION("""COMPUTED_VALUE"""),"Máy đào KOBELCO bánh xích gàu 1.2m3") -> Máy đào KOBELCO bánh xích gàu 1.2m3 | C4: =IFERROR(__xludf.DUMMYFUNCTION("""COMPUTED_VALUE"""),"CGTC DP") -> CGTC DP | D4: =IFERROR(__xludf.DUMMYFUNCTION("""COMPUTED_VALUE"""),"KOBELCO") -> KOBELCO | E4: =IFERROR(__xludf.DUMMYFUNCTION("""COMPUTED_VALUE"""),"NHẬT BẢN") -> NHẬT BẢN | F4: =IFERROR(__xludf.DUMMYFUNCTION("""COMPUTED_VALUE"""),2019) -> 2019 | G4: =IFERROR(__xludf.DUMMYFUNCTION("""COMPUTED_VALUE"""),"SK200-08") -> SK200-08 | H4: =IFERROR(__xludf.DUMMYFUNCTION("""COMPUTED_VALUE"""),"170HP") -> 170HP | I4: =IFERROR(__xludf.DUMMYFUNCTION("""COMPUTED_VALUE"""),"LQ16-10073 ") -> LQ16-10073 | J4: =IFERROR(__xludf.DUMMYFUNCTION("""COMPUTED_VALUE"""),"R0033333") -> R0033333 | K4: =IFERROR(__xludf.DUMMYFUNCTION("""COMPUTED_VALUE"""),17) -> 17 | L4: =IFERROR(__xludf.DUMMYFUNCTION("""COMPUTED_VALUE"""),"KLH") -> KLH
A5: =IFERROR(__xludf.DUMMYFUNCTION("""COMPUTED_VALUE"""),"CHT-MĐA-002") -> CHT-MĐA-002 | B5: =IFERROR(__xludf.DUMMYFUNCTION("""COMPUTED_VALUE"""),"Máy đào SH210 bánh xích gàu 0.9m3") -> Máy đào SH210 bánh xích gàu 0.9m3 | C5: =IFERROR(__xludf.DUMMYFUNCTION("""COMPUTED_VALUE"""),"CGTC DP") -> CGTC DP | D5: =IFERROR(__xludf.DUMMYFUNCTION("""COMPUTED_VALUE"""),"SUMITOMO") -> SUMITOMO | E5: =IFERROR(__xludf.DUMMYFUNCTION("""COMPUTED_VALUE"""),"NHẬT BẢN") -> NHẬT BẢN | F5: =IFERROR(__xludf.DUMMYFUNCTION("""COMPUTED_VALUE"""),1993) -> 1993 | G5: =IFERROR(__xludf.DUMMYFUNCTION("""COMPUTED_VALUE"""),"SH210") -> SH210 | H5: =IFERROR(__xludf.DUMMYFUNCTION("""COMPUTED_VALUE"""),"156HP") -> 156HP | I5: =IFERROR(__xludf.DUMMYFUNCTION("""COMPUTED_VALUE"""),"STN210T6P00BH2390") -> STN210T6P00BH2390 | J5: =IFERROR(__xludf.DUMMYFUNCTION("""COMPUTED_VALUE"""),"CCN") -> CCN | K5: =IFERROR(__xludf.DUMMYFUNCTION("""COMPUTED_VALUE"""),13) -> 13 | L5: =IFERROR(__xludf.DUMMYFUNCTION("""COMPUTED_VALUE"""),"KLH") -> KLH
A6: =IFERROR(__xludf.DUMMYFUNCTION("""COMPUTED_VALUE"""),"CHT-MĐA-003") -> CHT-MĐA-003 | B6: =IFERROR(__xludf.DUMMYFUNCTION("""COMPUTED_VALUE"""),"Máy đào DX140W bánh lốp gàu 0.7m3") -> Máy đào DX140W bánh lốp gàu 0.7m3 | C6: =IFERROR(__xludf.DUMMYFUNCTION("""COMPUTED_VALUE"""),"CGTC DP") -> CGTC DP | D6: =IFERROR(__xludf.DUMMYFUNCTION("""COMPUTED_VALUE"""),"DOOSAN") -> DOOSAN | E6: =IFERROR(__xludf.DUMMYFUNCTION("""COMPUTED_VALUE"""),"HÀN QUỐC") -> HÀN QUỐC | F6: =IFERROR(__xludf.DUMMYFUNCTION("""COMPUTED_VALUE"""),2019) -> 2019 | G6: =IFERROR(__xludf.DUMMYFUNCTION("""COMPUTED_VALUE"""),"DX140W") -> DX140W | H6: =IFERROR(__xludf.DUMMYFUNCTION("""COMPUTED_VALUE"""),"133HP") -> 133HP | I6: =IFERROR(__xludf.DUMMYFUNCTION("""COMPUTED_VALUE"""),"DHKCEWAAVK5008713") -> DHKCEWAAVK5008713 | J6: =IFERROR(__xludf.DUMMYFUNCTION("""COMPUTED_VALUE"""),"CCN") -> CCN | K6: =IFERROR(__xludf.DUMMYFUNCTION("""COMPUTED_VALUE"""),10) -> 10 | L6: =IFERROR(__xludf.DUMMYFUNCTION("""COMPUTED_VALUE"""),"KLH") -> KLH
A7: =IFERROR(__xludf.DUMMYFUNCTION("""COMPUTED_VALUE"""),"CHT-MĐA-004") -> CHT-MĐA-004 | B7: =IFERROR(__xludf.DUMMYFUNCTION("""COMPUTED_VALUE"""),"Máy đào DX140W bánh lốp gàu 0.7m3") -> Máy đào DX140W bánh lốp gàu 0.7m3 | C7: =IFERROR(__xludf.DUMMYFUNCTION("""COMPUTED_VALUE"""),"CGTC DP") -> CGTC DP | D7: =IFERROR(__xludf.DUMMYFUNCTION("""COMPUTED_VALUE"""),"DOOSAN") -> DOOSAN | E7: =IFERROR(__xludf.DUMMYFUNCTION("""COMPUTED_VALUE"""),"HÀN QUỐC") -> HÀN QUỐC | F7: =IFERROR(__xludf.DUMMYFUNCTION("""COMPUTED_VALUE"""),2018) -> 2018 | G7: =IFERROR(__xludf.DUMMYFUNCTION("""COMPUTED_VALUE"""),"DX140W") -> DX140W | H7: =IFERROR(__xludf.DUMMYFUNCTION("""COMPUTED_VALUE"""),"133HP") -> 133HP | I7: =IFERROR(__xludf.DUMMYFUNCTION("""COMPUTED_VALUE"""),"DHKCEWAAEK5008652") -> DHKCEWAAEK5008652 | J7: =IFERROR(__xludf.DUMMYFUNCTION("""COMPUTED_VALUE"""),"CCN") -> CCN | K7: =IFERROR(__xludf.DUMMYFUNCTION("""COMPUTED_VALUE"""),10) -> 10 | L7: =IFERROR(__xludf.DUMMYFUNCTION("""COMPUTED_VALUE"""),"KLH") -> KLH
A8: =IFERROR(__xludf.DUMMYFUNCTION("""COMPUTED_VALUE"""),"CHT-MĐA-044") -> CHT-MĐA-044 | B8: =IFERROR(__xludf.DUMMYFUNCTION("""COMPUTED_VALUE"""),"Máy đào SH210 bánh xích gàu 0.9m3") -> Máy đào SH210 bánh xích gàu 0.9m3 | C8: =IFERROR(__xludf.DUMMYFUNCTION("""COMPUTED_VALUE"""),"CGTC DP") -> CGTC DP | D8: =IFERROR(__xludf.DUMMYFUNCTION("""COMPUTED_VALUE"""),"SUMITOMO") -> SUMITOMO | E8: =IFERROR(__xludf.DUMMYFUNCTION("""COMPUTED_VALUE"""),"NHẬT BẢN") -> NHẬT BẢN | F8: =IFERROR(__xludf.DUMMYFUNCTION("""COMPUTED_VALUE"""),2020) -> 2020 | G8: =IFERROR(__xludf.DUMMYFUNCTION("""COMPUTED_VALUE"""),"SH210-6") -> SH210-6 | H8: =IFERROR(__xludf.DUMMYFUNCTION("""COMPUTED_VALUE"""),"160HP") -> 160HP | I8: =IFERROR(__xludf.DUMMYFUNCTION("""COMPUTED_VALUE"""),"STN210T6P00BH2695") -> STN210T6P00BH2695 | J8: =IFERROR(__xludf.DUMMYFUNCTION("""COMPUTED_VALUE"""),"801502") -> 801502 | K8: =IFERROR(__xludf.DUMMYFUNCTION("""COMPUTED_VALUE"""),13) -> 13 | L8: =IFERROR(__xludf.DUMMYFUNCTION("""COMPUTED_VALUE"""),"KLH") -> KLH
A9: =IFERROR(__xludf.DUMMYFUNCTION("""COMPUTED_VALUE"""),"CHT-MĐA-045") -> CHT-MĐA-045 | B9: =IFERROR(__xludf.DUMMYFUNCTION("""COMPUTED_VALUE"""),"Máy đào SH130 bánh xích gàu 0.5m3") -> Máy đào SH130 bánh xích gàu 0.5m3 | C9: =IFERROR(__xludf.DUMMYFUNCTION("""COMPUTED_VALUE"""),"CGTC DP") -> CGTC DP | D9: =IFERROR(__xludf.DUMMYFUNCTION("""COMPUTED_VALUE"""),"SUMITOMO") -> SUMITOMO | E9: =IFERROR(__xludf.DUMMYFUNCTION("""COMPUTED_VALUE"""),"NHẬT BẢN") -> NHẬT BẢN | F9: =IFERROR(__xludf.DUMMYFUNCTION("""COMPUTED_VALUE"""),2021) -> 2021 | G9: =IFERROR(__xludf.DUMMYFUNCTION("""COMPUTED_VALUE"""),"SH130-6") -> SH130-6 | H9: =IFERROR(__xludf.DUMMYFUNCTION("""COMPUTED_VALUE"""),"96HP") -> 96HP | I9: =IFERROR(__xludf.DUMMYFUNCTION("""COMPUTED_VALUE"""),"STN130T6A00BH1835") -> STN130T6A00BH1835 | J9: =IFERROR(__xludf.DUMMYFUNCTION("""COMPUTED_VALUE"""),"6041164JJ1") -> 6041164JJ1 | K9: =IFERROR(__xludf.DUMMYFUNCTION("""COMPUTED_VALUE"""),12) -> 12 | L9: =IFERROR(__xludf.DUMMYFUNCTION("""COMPUTED_VALUE"""),"KLH") -> KLH
A10: =IFERROR(__xludf.DUMMYFUNCTION("""COMPUTED_VALUE"""),"CHT-MUI-001") -> CHT-MUI-001 | B10: =IFERROR(__xludf.DUMMYFUNCTION("""COMPUTED_VALUE"""),"Máy ủi KOMATSU D31PX") -> Máy ủi KOMATSU D31PX | C10: =IFERROR(__xludf.DUMMYFUNCTION("""COMPUTED_VALUE"""),"CGTC DP") -> CGTC DP | D10: =IFERROR(__xludf.DUMMYFUNCTION("""COMPUTED_VALUE"""),"KOMATSU") -> KOMATSU | E10: =IFERROR(__xludf.DUMMYFUNCTION("""COMPUTED_VALUE"""),"NHẬT BẢN") -> NHẬT BẢN | F10: =IFERROR(__xludf.DUMMYFUNCTION("""COMPUTED_VALUE"""),1997) -> 1997 | G10: =IFERROR(__xludf.DUMMYFUNCTION("""COMPUTED_VALUE"""),"D31PX") -> D31PX | H10: =IFERROR(__xludf.DUMMYFUNCTION("""COMPUTED_VALUE"""),"80HP") -> 80HP | I10: =IFERROR(__xludf.DUMMYFUNCTION("""COMPUTED_VALUE"""),"KMT0D007V0151352") -> KMT0D007V0151352 | J10: =IFERROR(__xludf.DUMMYFUNCTION("""COMPUTED_VALUE"""),"CCN") -> CCN | K10: =IFERROR(__xludf.DUMMYFUNCTION("""COMPUTED_VALUE"""),8) -> 8 | L10: =IFERROR(__xludf.DUMMYFUNCTION("""COMPUTED_VALUE"""),"KLH") -> KLH
A11: =IFERROR(__xludf.DUMMYFUNCTION("""COMPUTED_VALUE"""),"CHT-MUI-002") -> CHT-MUI-002 | B11: =IFERROR(__xludf.DUMMYFUNCTION("""COMPUTED_VALUE"""),"Máy ủi KOMATSU D60P-12E") -> Máy ủi KOMATSU D60P-12E | C11: =IFERROR(__xludf.DUMMYFUNCTION("""COMPUTED_VALUE"""),"CGTC DP") -> CGTC DP | D11: =IFERROR(__xludf.DUMMYFUNCTION("""COMPUTED_VALUE"""),"KOMATSU") -> KOMATSU | E11: =IFERROR(__xludf.DUMMYFUNCTION("""COMPUTED_VALUE"""),"NHẬT BẢN") -> NHẬT BẢN | F11: =IFERROR(__xludf.DUMMYFUNCTION("""COMPUTED_VALUE"""),2002) -> 2002 | G11: =IFERROR(__xludf.DUMMYFUNCTION("""COMPUTED_VALUE"""),"D60P-12E") -> D60P-12E | H11: =IFERROR(__xludf.DUMMYFUNCTION("""COMPUTED_VALUE"""),"190HP") -> 190HP | I11: =IFERROR(__xludf.DUMMYFUNCTION("""COMPUTED_VALUE"""),"D60P1260763") -> D60P1260763 | J11: =IFERROR(__xludf.DUMMYFUNCTION("""COMPUTED_VALUE"""),"CCN") -> CCN | K11: =IFERROR(__xludf.DUMMYFUNCTION("""COMPUTED_VALUE"""),14) -> 14 | L11: =IFERROR(__xludf.DUMMYFUNCTION("""COMPUTED_VALUE"""),"KLH") -> KLH
A12: =IFERROR(__xludf.DUMMYFUNCTION("""COMPUTED_VALUE"""),"CHT-MUI-010") -> CHT-MUI-010 | B12: =IFERROR(__xludf.DUMMYFUNCTION("""COMPUTED_VALUE"""),"Máy ủi KOMATSU D65P-12") -> Máy ủi KOMATSU D65P-12 | C12: =IFERROR(__xludf.DUMMYFUNCTION("""COMPUTED_VALUE"""),"CGTC DP") -> CGTC DP | D12: =IFERROR(__xludf.DUMMYFUNCTION("""COMPUTED_VALUE"""),"KOMATSU") -> KOMATSU | E12: =IFERROR(__xludf.DUMMYFUNCTION("""COMPUTED_VALUE"""),"NHẬT BẢN") -> NHẬT BẢN | F12: =IFERROR(__xludf.DUMMYFUNCTION("""COMPUTED_VALUE"""),1992) -> 1992 | G12: =IFERROR(__xludf.DUMMYFUNCTION("""COMPUTED_VALUE"""),"D65P-12") -> D65P-12 | H12: =IFERROR(__xludf.DUMMYFUNCTION("""COMPUTED_VALUE"""),"190HP") -> 190HP | I12: =IFERROR(__xludf.DUMMYFUNCTION("""COMPUTED_VALUE"""),"D65P1260304") -> D65P1260304 | J12: =IFERROR(__xludf.DUMMYFUNCTION("""COMPUTED_VALUE"""),"6D12554976") -> 6D12554976 | K12: =IFERROR(__xludf.DUMMYFUNCTION("""COMPUTED_VALUE"""),14) -> 14 | L12: =IFERROR(__xludf.DUMMYFUNCTION("""COMPUTED_VALUE"""),"KLH") -> KLH
A13: =IFERROR(__xludf.DUMMYFUNCTION("""COMPUTED_VALUE"""),"CHT-MUI-013") -> CHT-MUI-013 | B13: =IFERROR(__xludf.DUMMYFUNCTION("""COMPUTED_VALUE"""),"Máy ủi KOMATSU D60P-12E") -> Máy ủi KOMATSU D60P-12E | C13: =IFERROR(__xludf.DUMMYFUNCTION("""COMPUTED_VALUE"""),"CGTC DP") -> CGTC DP | D13: =IFERROR(__xludf.DUMMYFUNCTION("""COMPUTED_VALUE"""),"KOMATSU") -> KOMATSU | E13: =IFERROR(__xludf.DUMMYFUNCTION("""COMPUTED_VALUE"""),"NHẬT BẢN") -> NHẬT BẢN | F13: =IFERROR(__xludf.DUMMYFUNCTION("""COMPUTED_VALUE"""),1994) -> 1994 | G13: =IFERROR(__xludf.DUMMYFUNCTION("""COMPUTED_VALUE"""),"D60P-12E") -> D60P-12E | H13: =IFERROR(__xludf.DUMMYFUNCTION("""COMPUTED_VALUE"""),"190HP") -> 190HP | I13: =IFERROR(__xludf.DUMMYFUNCTION("""COMPUTED_VALUE"""),"D60P1260928") -> D60P1260928 | J13: =IFERROR(__xludf.DUMMYFUNCTION("""COMPUTED_VALUE"""),"6D12562174") -> 6D12562174 | K13: =IFERROR(__xludf.DUMMYFUNCTION("""COMPUTED_VALUE"""),14) -> 14 | L13: =IFERROR(__xludf.DUMMYFUNCTION("""COMPUTED_VALUE"""),"KLH") -> KLH
A14: =IFERROR(__xludf.DUMMYFUNCTION("""COMPUTED_VALUE"""),"CHT-XTA-014") -> CHT-XTA-014 | B14: =IFERROR(__xludf.DUMMYFUNCTION("""COMPUTED_VALUE"""),"Xe ben AUMAN GTL D300 E4") -> Xe ben AUMAN GTL D300 E4 | C14: =IFERROR(__xludf.DUMMYFUNCTION("""COMPUTED_VALUE"""),"CGTC DP") -> CGTC DP | D14: =IFERROR(__xludf.DUMMYFUNCTION("""COMPUTED_VALUE"""),"THACO AUMAN") -> THACO AUMAN | E14: =IFERROR(__xludf.DUMMYFUNCTION("""COMPUTED_VALUE"""),"VIỆT NAM") -> VIỆT NAM | F14: =IFERROR(__xludf.DUMMYFUNCTION("""COMPUTED_VALUE"""),2018) -> 2018 | G14: =IFERROR(__xludf.DUMMYFUNCTION("""COMPUTED_VALUE"""),"GTL D300E4") -> GTL D300E4 | H14: =IFERROR(__xludf.DUMMYFUNCTION("""COMPUTED_VALUE"""),"375HP") -> 375HP | I14: =IFERROR(__xludf.DUMMYFUNCTION("""COMPUTED_VALUE"""),"RNHD30FWAJC078089") -> RNHD30FWAJC078089 | J14: =IFERROR(__xludf.DUMMYFUNCTION("""COMPUTED_VALUE"""),"CCN") -> CCN | K14: =IFERROR(__xludf.DUMMYFUNCTION("""COMPUTED_VALUE"""),1.41) -> 1.41 | L14: =IFERROR(__xludf.DUMMYFUNCTION("""COMPUTED_VALUE"""),"KLH") -> KLH
A15: =IFERROR(__xludf.DUMMYFUNCTION("""COMPUTED_VALUE"""),"CHT-XTA-024") -> CHT-XTA-024 | B15: =IFERROR(__xludf.DUMMYFUNCTION("""COMPUTED_VALUE"""),"Xe ben HOWO TXD600") -> Xe ben HOWO TXD600 | C15: =IFERROR(__xludf.DUMMYFUNCTION("""COMPUTED_VALUE"""),"CGTC DP") -> CGTC DP | D15: =IFERROR(__xludf.DUMMYFUNCTION("""COMPUTED_VALUE"""),"HOWO") -> HOWO | E15: =IFERROR(__xludf.DUMMYFUNCTION("""COMPUTED_VALUE"""),"VIỆT NAM") -> VIỆT NAM | F15: =IFERROR(__xludf.DUMMYFUNCTION("""COMPUTED_VALUE"""),2022) -> 2022 | G15: =IFERROR(__xludf.DUMMYFUNCTION("""COMPUTED_VALUE"""),"HOWO TX D600") -> HOWO TX D600 | H15: =IFERROR(__xludf.DUMMYFUNCTION("""COMPUTED_VALUE"""),"380HP") -> 380HP | I15: =IFERROR(__xludf.DUMMYFUNCTION("""COMPUTED_VALUE"""),"RNHD24CWANT057806") -> RNHD24CWANT057806 | J15: =IFERROR(__xludf.DUMMYFUNCTION("""COMPUTED_VALUE"""),"1622B008395") -> 1622B008395 | K15: =IFERROR(__xludf.DUMMYFUNCTION("""COMPUTED_VALUE"""),1.34) -> 1.34 | L15: =IFERROR(__xludf.DUMMYFUNCTION("""COMPUTED_VALUE"""),"KLH") -> KLH
A16: =IFERROR(__xludf.DUMMYFUNCTION("""COMPUTED_VALUE"""),"CHT-XTA-025") -> CHT-XTA-025 | B16: =IFERROR(__xludf.DUMMYFUNCTION("""COMPUTED_VALUE"""),"Xe ben HOWO TXD600") -> Xe ben HOWO TXD600 | C16: =IFERROR(__xludf.DUMMYFUNCTION("""COMPUTED_VALUE"""),"CGTC DP") -> CGTC DP | D16: =IFERROR(__xludf.DUMMYFUNCTION("""COMPUTED_VALUE"""),"HOWO") -> HOWO | E16: =IFERROR(__xludf.DUMMYFUNCTION("""COMPUTED_VALUE"""),"VIỆT NAM") -> VIỆT NAM | F16: =IFERROR(__xludf.DUMMYFUNCTION("""COMPUTED_VALUE"""),2022) -> 2022 | G16: =IFERROR(__xludf.DUMMYFUNCTION("""COMPUTED_VALUE"""),"HOWO TX D600") -> HOWO TX D600 | H16: =IFERROR(__xludf.DUMMYFUNCTION("""COMPUTED_VALUE"""),"380HP") -> 380HP | I16: =IFERROR(__xludf.DUMMYFUNCTION("""COMPUTED_VALUE"""),"RNHD24CWANT057808") -> RNHD24CWANT057808 | J16: =IFERROR(__xludf.DUMMYFUNCTION("""COMPUTED_VALUE"""),"1622B008391") -> 1622B008391 | K16: =IFERROR(__xludf.DUMMYFUNCTION("""COMPUTED_VALUE"""),1.34) -> 1.34 | L16: =IFERROR(__xludf.DUMMYFUNCTION("""COMPUTED_VALUE"""),"KLH") -> KLH
A17: =IFERROR(__xludf.DUMMYFUNCTION("""COMPUTED_VALUE"""),"CHT-XTA-026") -> CHT-XTA-026 | B17: =IFERROR(__xludf.DUMMYFUNCTION("""COMPUTED_VALUE"""),"Xe ben HOWO TXD600") -> Xe ben HOWO TXD600 | C17: =IFERROR(__xludf.DUMMYFUNCTION("""COMPUTED_VALUE"""),"CGTC DP") -> CGTC DP | D17: =IFERROR(__xludf.DUMMYFUNCTION("""COMPUTED_VALUE"""),"HOWO") -> HOWO | E17: =IFERROR(__xludf.DUMMYFUNCTION("""COMPUTED_VALUE"""),"VIỆT NAM") -> VIỆT NAM | F17: =IFERROR(__xludf.DUMMYFUNCTION("""COMPUTED_VALUE"""),2022) -> 2022 | G17: =IFERROR(__xludf.DUMMYFUNCTION("""COMPUTED_VALUE"""),"HOWO TX D600") -> HOWO TX D600 | H17: =IFERROR(__xludf.DUMMYFUNCTION("""COMPUTED_VALUE"""),"380HP") -> 380HP | I17: =IFERROR(__xludf.DUMMYFUNCTION("""COMPUTED_VALUE"""),"RNHD24CWANT057810") -> RNHD24CWANT057810 | J17: =IFERROR(__xludf.DUMMYFUNCTION("""COMPUTED_VALUE"""),"1622B008389") -> 1622B008389 | K17: =IFERROR(__xludf.DUMMYFUNCTION("""COMPUTED_VALUE"""),0.9) -> 0.9 | L17: =IFERROR(__xludf.DUMMYFUNCTION("""COMPUTED_VALUE"""),"KLH") -> KLH
A18: =IFERROR(__xludf.DUMMYFUNCTION("""COMPUTED_VALUE"""),"CHT-XTA-036") -> CHT-XTA-036 | B18: =IFERROR(__xludf.DUMMYFUNCTION("""COMPUTED_VALUE"""),"Xe ben HOWO TXD600") -> Xe ben HOWO TXD600 | C18: =IFERROR(__xludf.DUMMYFUNCTION("""COMPUTED_VALUE"""),"CGTC DP") -> CGTC DP | D18: =IFERROR(__xludf.DUMMYFUNCTION("""COMPUTED_VALUE"""),"HOWO") -> HOWO | E18: =IFERROR(__xludf.DUMMYFUNCTION("""COMPUTED_VALUE"""),"VIỆT NAM") -> VIỆT NAM | F18: =IFERROR(__xludf.DUMMYFUNCTION("""COMPUTED_VALUE"""),2022) -> 2022 | G18: =IFERROR(__xludf.DUMMYFUNCTION("""COMPUTED_VALUE"""),"HOWO TX D600") -> HOWO TX D600 | H18: =IFERROR(__xludf.DUMMYFUNCTION("""COMPUTED_VALUE"""),"380HP") -> 380HP | I18: =IFERROR(__xludf.DUMMYFUNCTION("""COMPUTED_VALUE"""),"RNHD24CWART000069") -> RNHD24CWART000069 | J18: =IFERROR(__xludf.DUMMYFUNCTION("""COMPUTED_VALUE"""),"1622F024360") -> 1622F024360 | K18: =IFERROR(__xludf.DUMMYFUNCTION("""COMPUTED_VALUE"""),1.34) -> 1.34 | L18: =IFERROR(__xludf.DUMMYFUNCTION("""COMPUTED_VALUE"""),"KLH") -> KLH
A19: =IFERROR(__xludf.DUMMYFUNCTION("""COMPUTED_VALUE"""),"CHT-XLU-001") -> CHT-XLU-001 | B19: =IFERROR(__xludf.DUMMYFUNCTION("""COMPUTED_VALUE"""),"Xe lu rung SV521DH 11 tấn") -> Xe lu rung SV521DH 11 tấn | C19: =IFERROR(__xludf.DUMMYFUNCTION("""COMPUTED_VALUE"""),"CGTC DP") -> CGTC DP | D19: =IFERROR(__xludf.DUMMYFUNCTION("""COMPUTED_VALUE"""),"SAKAI") -> SAKAI | E19: =IFERROR(__xludf.DUMMYFUNCTION("""COMPUTED_VALUE"""),"NHẬT BẢN") -> NHẬT BẢN | F19: =IFERROR(__xludf.DUMMYFUNCTION("""COMPUTED_VALUE"""),2006) -> 2006 | G19: =IFERROR(__xludf.DUMMYFUNCTION("""COMPUTED_VALUE"""),"SV521DH") -> SV521DH | H19: =IFERROR(__xludf.DUMMYFUNCTION("""COMPUTED_VALUE"""),"112HP") -> 112HP | I19: =IFERROR(__xludf.DUMMYFUNCTION("""COMPUTED_VALUE"""),"2SV6610202") -> 2SV6610202 | J19: =IFERROR(__xludf.DUMMYFUNCTION("""COMPUTED_VALUE"""),"CCN") -> CCN | K19: =IFERROR(__xludf.DUMMYFUNCTION("""COMPUTED_VALUE"""),7) -> 7 | L19: =IFERROR(__xludf.DUMMYFUNCTION("""COMPUTED_VALUE"""),"KLH") -> KLH
A20: =IFERROR(__xludf.DUMMYFUNCTION("""COMPUTED_VALUE"""),"CHT-XLU-002") -> CHT-XLU-002 | B20: =IFERROR(__xludf.DUMMYFUNCTION("""COMPUTED_VALUE"""),"Xe lu tĩnh R2 10 tấn") -> Xe lu tĩnh R2 10 tấn | C20: =IFERROR(__xludf.DUMMYFUNCTION("""COMPUTED_VALUE"""),"CGTC DP") -> CGTC DP | D20: =IFERROR(__xludf.DUMMYFUNCTION("""COMPUTED_VALUE"""),"SAKAI") -> SAKAI | E20: =IFERROR(__xludf.DUMMYFUNCTION("""COMPUTED_VALUE"""),"NHẬT BẢN") -> NHẬT BẢN | F20: =IFERROR(__xludf.DUMMYFUNCTION("""COMPUTED_VALUE"""),1990) -> 1990 | G20: =IFERROR(__xludf.DUMMYFUNCTION("""COMPUTED_VALUE"""),"R2S") -> R2S | H20: =IFERROR(__xludf.DUMMYFUNCTION("""COMPUTED_VALUE"""),"74HP") -> 74HP | I20: =IFERROR(__xludf.DUMMYFUNCTION("""COMPUTED_VALUE"""),"RR211446") -> RR211446 | J20: =IFERROR(__xludf.DUMMYFUNCTION("""COMPUTED_VALUE"""),"W04DA26254") -> W04DA26254 | K20: =IFERROR(__xludf.DUMMYFUNCTION("""COMPUTED_VALUE"""),4) -> 4 | L20: =IFERROR(__xludf.DUMMYFUNCTION("""COMPUTED_VALUE"""),"KLH") -> KLH
A21: =IFERROR(__xludf.DUMMYFUNCTION("""COMPUTED_VALUE"""),"CHT-XBO-005") -> CHT-XBO-005 | B21: =IFERROR(__xludf.DUMMYFUNCTION("""COMPUTED_VALUE"""),"Xe bồn AUMAN ETX D300 (tưới đường)") -> Xe bồn AUMAN ETX D300 (tưới đường) | C21: =IFERROR(__xludf.DUMMYFUNCTION("""COMPUTED_VALUE"""),"CGTC DP") -> CGTC DP | D21: =IFERROR(__xludf.DUMMYFUNCTION("""COMPUTED_VALUE"""),"AUMAN") -> AUMAN | E21: =IFERROR(__xludf.DUMMYFUNCTION("""COMPUTED_VALUE"""),"VIỆT NAM") -> VIỆT NAM | F21: =IFERROR(__xludf.DUMMYFUNCTION("""COMPUTED_VALUE"""),2022) -> 2022 | G21: =IFERROR(__xludf.DUMMYFUNCTION("""COMPUTED_VALUE""")," ETX D300") -> ETX D300 | H21: =IFERROR(__xludf.DUMMYFUNCTION("""COMPUTED_VALUE"""),"330HP") -> 330HP | I21: =IFERROR(__xludf.DUMMYFUNCTION("""COMPUTED_VALUE"""),"RNHD30FWANT067862") -> RNHD30FWANT067862 | J21: =IFERROR(__xludf.DUMMYFUNCTION("""COMPUTED_VALUE"""),"WP10336E431622D017084") -> WP10336E431622D017084 | K21: =IFERROR(__xludf.DUMMYFUNCTION("""COMPUTED_VALUE"""),0.6) -> 0.6 | L21: =IFERROR(__xludf.DUMMYFUNCTION("""COMPUTED_VALUE"""),"KLH") -> KLH
A22: =IFERROR(__xludf.DUMMYFUNCTION("""COMPUTED_VALUE"""),"CHT-BAN-003") -> CHT-BAN-003 | B22: =IFERROR(__xludf.DUMMYFUNCTION("""COMPUTED_VALUE"""),"Xe ban KOMATSU GD605A") -> Xe ban KOMATSU GD605A | C22: =IFERROR(__xludf.DUMMYFUNCTION("""COMPUTED_VALUE"""),"CGTC DP") -> CGTC DP | D22: =IFERROR(__xludf.DUMMYFUNCTION("""COMPUTED_VALUE"""),"KOMATSU") -> KOMATSU | E22: =IFERROR(__xludf.DUMMYFUNCTION("""COMPUTED_VALUE"""),"NHẬT BẢN") -> NHẬT BẢN | F22: =IFERROR(__xludf.DUMMYFUNCTION("""COMPUTED_VALUE"""),1994) -> 1994 | G22: =IFERROR(__xludf.DUMMYFUNCTION("""COMPUTED_VALUE"""),"GD605A-5") -> GD605A-5 | H22: =IFERROR(__xludf.DUMMYFUNCTION("""COMPUTED_VALUE"""),"145HP") -> 145HP | I22: =IFERROR(__xludf.DUMMYFUNCTION("""COMPUTED_VALUE"""),"G605A54617") -> G605A54617 | J22: =IFERROR(__xludf.DUMMYFUNCTION("""COMPUTED_VALUE"""),"6D12561378") -> 6D12561378 | K22: =IFERROR(__xludf.DUMMYFUNCTION("""COMPUTED_VALUE"""),9.3) -> 9.3 | L22: =IFERROR(__xludf.DUMMYFUNCTION("""COMPUTED_VALUE"""),"KLH") -> KLH
A23: =IFERROR(__xludf.DUMMYFUNCTION("""COMPUTED_VALUE"""),"CHT-BAN-001") -> CHT-BAN-001 | B23: =IFERROR(__xludf.DUMMYFUNCTION("""COMPUTED_VALUE"""),"Xe ban Komatsu 705A") -> Xe ban Komatsu 705A | C23: =IFERROR(__xludf.DUMMYFUNCTION("""COMPUTED_VALUE"""),"CGTC DP") -> CGTC DP | D23: =IFERROR(__xludf.DUMMYFUNCTION("""COMPUTED_VALUE"""),"KOMATSU") -> KOMATSU | E23: =IFERROR(__xludf.DUMMYFUNCTION("""COMPUTED_VALUE"""),"NHẬT BẢN") -> NHẬT BẢN | F23: =IFERROR(__xludf.DUMMYFUNCTION("""COMPUTED_VALUE"""),2018) -> 2018 | G23: =IFERROR(__xludf.DUMMYFUNCTION("""COMPUTED_VALUE"""),"705A") -> 705A | H23: =IFERROR(__xludf.DUMMYFUNCTION("""COMPUTED_VALUE"""),"200HP") -> 200HP | I23: =IFERROR(__xludf.DUMMYFUNCTION("""COMPUTED_VALUE"""),"G70A4A11006") -> G70A4A11006 | J23: =IFERROR(__xludf.DUMMYFUNCTION("""COMPUTED_VALUE"""),"CCN") -> CCN | K23: =IFERROR(__xludf.DUMMYFUNCTION("""COMPUTED_VALUE"""),14.8) -> 14.8 | L23: =IFERROR(__xludf.DUMMYFUNCTION("""COMPUTED_VALUE"""),"KLH") -> KLH
A24: =IFERROR(__xludf.DUMMYFUNCTION("""COMPUTED_VALUE"""),"CHT-MĐA-058") -> CHT-MĐA-058 | B24: =IFERROR(__xludf.DUMMYFUNCTION("""COMPUTED_VALUE"""),"Máy đào KOMATSU bánh xích gàu 0.3m3") -> Máy đào KOMATSU bánh xích gàu 0.3m3 | C24: =IFERROR(__xludf.DUMMYFUNCTION("""COMPUTED_VALUE"""),"CGTC DP") -> CGTC DP | D24: =IFERROR(__xludf.DUMMYFUNCTION("""COMPUTED_VALUE"""),"KOMATSU") -> KOMATSU | E24: =IFERROR(__xludf.DUMMYFUNCTION("""COMPUTED_VALUE"""),"NHẬT BẢN") -> NHẬT BẢN | F24: =IFERROR(__xludf.DUMMYFUNCTION("""COMPUTED_VALUE"""),2015) -> 2015 | G24: =IFERROR(__xludf.DUMMYFUNCTION("""COMPUTED_VALUE"""),"PC40MR-3") -> PC40MR-3 | H24: =IFERROR(__xludf.DUMMYFUNCTION("""COMPUTED_VALUE"""),"40HP") -> 40HP | I24: =IFERROR(__xludf.DUMMYFUNCTION("""COMPUTED_VALUE"""),"KMTPC212VFE019356") -> KMTPC212VFE019356 | J24: =IFERROR(__xludf.DUMMYFUNCTION("""COMPUTED_VALUE"""),"38204") -> 38204 | K24: =IFERROR(__xludf.DUMMYFUNCTION("""COMPUTED_VALUE"""),4) -> 4 | L24: =IFERROR(__xludf.DUMMYFUNCTION("""COMPUTED_VALUE"""),"KLH") -> KLH
A25: =IFERROR(__xludf.DUMMYFUNCTION("""COMPUTED_VALUE"""),"CHT-MĐA-059") -> CHT-MĐA-059 | B25: =IFERROR(__xludf.DUMMYFUNCTION("""COMPUTED_VALUE"""),"Máy đào KOMATSU bánh xích gàu 0.3m3") -> Máy đào KOMATSU bánh xích gàu 0.3m3 | C25: =IFERROR(__xludf.DUMMYFUNCTION("""COMPUTED_VALUE"""),"CGTC DP") -> CGTC DP | D25: =IFERROR(__xludf.DUMMYFUNCTION("""COMPUTED_VALUE"""),"KOMATSU") -> KOMATSU | E25: =IFERROR(__xludf.DUMMYFUNCTION("""COMPUTED_VALUE"""),"NHẬT BẢN") -> NHẬT BẢN | F25: =IFERROR(__xludf.DUMMYFUNCTION("""COMPUTED_VALUE"""),2012) -> 2012 | G25: =IFERROR(__xludf.DUMMYFUNCTION("""COMPUTED_VALUE"""),"PC40MR-3") -> PC40MR-3 | H25: =IFERROR(__xludf.DUMMYFUNCTION("""COMPUTED_VALUE"""),"40HP") -> 40HP | I25: =IFERROR(__xludf.DUMMYFUNCTION("""COMPUTED_VALUE"""),"KMTPC203L04019805") -> KMTPC203L04019805 | J25: =IFERROR(__xludf.DUMMYFUNCTION("""COMPUTED_VALUE"""),"25866") -> 25866 | K25: =IFERROR(__xludf.DUMMYFUNCTION("""COMPUTED_VALUE"""),4) -> 4 | L25: =IFERROR(__xludf.DUMMYFUNCTION("""COMPUTED_VALUE"""),"KLH") -> KLH
A26: =IFERROR(__xludf.DUMMYFUNCTION("""COMPUTED_VALUE"""),"CHT-MĐA-060") -> CHT-MĐA-060 | B26: =IFERROR(__xludf.DUMMYFUNCTION("""COMPUTED_VALUE"""),"Máy đào KOMATSU bánh xích gàu 0.3m3") -> Máy đào KOMATSU bánh xích gàu 0.3m3 | C26: =IFERROR(__xludf.DUMMYFUNCTION("""COMPUTED_VALUE"""),"CGTC DP") -> CGTC DP | D26: =IFERROR(__xludf.DUMMYFUNCTION("""COMPUTED_VALUE"""),"KOMATSU") -> KOMATSU | E26: =IFERROR(__xludf.DUMMYFUNCTION("""COMPUTED_VALUE"""),"NHẬT BẢN") -> NHẬT BẢN | F26: =IFERROR(__xludf.DUMMYFUNCTION("""COMPUTED_VALUE"""),2015) -> 2015 | G26: =IFERROR(__xludf.DUMMYFUNCTION("""COMPUTED_VALUE"""),"PC40MR-3") -> PC40MR-3 | H26: =IFERROR(__xludf.DUMMYFUNCTION("""COMPUTED_VALUE"""),"40HP") -> 40HP | I26: =IFERROR(__xludf.DUMMYFUNCTION("""COMPUTED_VALUE"""),"KMTPC203AFE023466") -> KMTPC203AFE023466 | J26: =IFERROR(__xludf.DUMMYFUNCTION("""COMPUTED_VALUE"""),"36975") -> 36975 | K26: =IFERROR(__xludf.DUMMYFUNCTION("""COMPUTED_VALUE"""),4) -> 4 | L26: =IFERROR(__xludf.DUMMYFUNCTION("""COMPUTED_VALUE"""),"KLH") -> KLH
A27: =IFERROR(__xludf.DUMMYFUNCTION("""COMPUTED_VALUE"""),"CHT-MĐA-062") -> CHT-MĐA-062 | B27: =IFERROR(__xludf.DUMMYFUNCTION("""COMPUTED_VALUE"""),"Máy đào KOMATSU bánh xích gàu 0.3m3") -> Máy đào KOMATSU bánh xích gàu 0.3m3 | C27: =IFERROR(__xludf.DUMMYFUNCTION("""COMPUTED_VALUE"""),"CGTC DP") -> CGTC DP | D27: =IFERROR(__xludf.DUMMYFUNCTION("""COMPUTED_VALUE"""),"KOMATSU") -> KOMATSU | E27: =IFERROR(__xludf.DUMMYFUNCTION("""COMPUTED_VALUE"""),"NHẬT BẢN") -> NHẬT BẢN | F27: =IFERROR(__xludf.DUMMYFUNCTION("""COMPUTED_VALUE"""),2017) -> 2017 | G27: =IFERROR(__xludf.DUMMYFUNCTION("""COMPUTED_VALUE"""),"PC55MR-3") -> PC55MR-3 | H27: =IFERROR(__xludf.DUMMYFUNCTION("""COMPUTED_VALUE"""),"40HP") -> 40HP | I27: =IFERROR(__xludf.DUMMYFUNCTION("""COMPUTED_VALUE"""),"020242") -> 020242 | J27: =IFERROR(__xludf.DUMMYFUNCTION("""COMPUTED_VALUE"""),"10671") -> 10671 | K27: =IFERROR(__xludf.DUMMYFUNCTION("""COMPUTED_VALUE"""),4) -> 4 | L27: =IFERROR(__xludf.DUMMYFUNCTION("""COMPUTED_VALUE"""),"KLH") -> KLH
A28: =IFERROR(__xludf.DUMMYFUNCTION("""COMPUTED_VALUE"""),"CHT-MĐA-063") -> CHT-MĐA-063 | B28: =IFERROR(__xludf.DUMMYFUNCTION("""COMPUTED_VALUE"""),"Máy đào KOMATSU bánh xích gàu 0.3m3") -> Máy đào KOMATSU bánh xích gàu 0.3m3 | C28: =IFERROR(__xludf.DUMMYFUNCTION("""COMPUTED_VALUE"""),"CGTC DP") -> CGTC DP | D28: =IFERROR(__xludf.DUMMYFUNCTION("""COMPUTED_VALUE"""),"KOMATSU") -> KOMATSU | E28: =IFERROR(__xludf.DUMMYFUNCTION("""COMPUTED_VALUE"""),"NHẬT BẢN") -> NHẬT BẢN | F28: =IFERROR(__xludf.DUMMYFUNCTION("""COMPUTED_VALUE"""),2015) -> 2015 | G28: =IFERROR(__xludf.DUMMYFUNCTION("""COMPUTED_VALUE"""),"PC55MR-3") -> PC55MR-3 | H28: =IFERROR(__xludf.DUMMYFUNCTION("""COMPUTED_VALUE"""),"40HP") -> 40HP | I28: =IFERROR(__xludf.DUMMYFUNCTION("""COMPUTED_VALUE"""),"019139") -> 019139 | J28: =IFERROR(__xludf.DUMMYFUNCTION("""COMPUTED_VALUE"""),"36094") -> 36094 | K28: =IFERROR(__xludf.DUMMYFUNCTION("""COMPUTED_VALUE"""),4) -> 4 | L28: =IFERROR(__xludf.DUMMYFUNCTION("""COMPUTED_VALUE"""),"KLH") -> KLH
A29: =IFERROR(__xludf.DUMMYFUNCTION("""COMPUTED_VALUE"""),"CHT-MĐA-047") -> CHT-MĐA-047 | B29: =IFERROR(__xludf.DUMMYFUNCTION("""COMPUTED_VALUE"""),"Máy đào KOMATSU bánh xích gàu 0.3m3") -> Máy đào KOMATSU bánh xích gàu 0.3m3 | C29: =IFERROR(__xludf.DUMMYFUNCTION("""COMPUTED_VALUE"""),"CGTC DP") -> CGTC DP | D29: =IFERROR(__xludf.DUMMYFUNCTION("""COMPUTED_VALUE"""),"KOMATSU") -> KOMATSU | E29: =IFERROR(__xludf.DUMMYFUNCTION("""COMPUTED_VALUE"""),"NHẬT BẢN") -> NHẬT BẢN | F29: =IFERROR(__xludf.DUMMYFUNCTION("""COMPUTED_VALUE"""),2013) -> 2013 | G29: =IFERROR(__xludf.DUMMYFUNCTION("""COMPUTED_VALUE"""),"PC40MR-3") -> PC40MR-3 | H29: =IFERROR(__xludf.DUMMYFUNCTION("""COMPUTED_VALUE"""),"40HP") -> 40HP | I29: =IFERROR(__xludf.DUMMYFUNCTION("""COMPUTED_VALUE"""),"KMTPC203V04021194") -> KMTPC203V04021194 | J29: =IFERROR(__xludf.DUMMYFUNCTION("""COMPUTED_VALUE"""),"25275") -> 25275 | K29: =IFERROR(__xludf.DUMMYFUNCTION("""COMPUTED_VALUE"""),4) -> 4 | L29: =IFERROR(__xludf.DUMMYFUNCTION("""COMPUTED_VALUE"""),"KLH") -> KLH
A30: =IFERROR(__xludf.DUMMYFUNCTION("""COMPUTED_VALUE"""),"CHT-MĐA-048") -> CHT-MĐA-048 | B30: =IFERROR(__xludf.DUMMYFUNCTION("""COMPUTED_VALUE"""),"Máy đào KOMATSU bánh xích gàu 0.3m3") -> Máy đào KOMATSU bánh xích gàu 0.3m3 | C30: =IFERROR(__xludf.DUMMYFUNCTION("""COMPUTED_VALUE"""),"CGTC DP") -> CGTC DP | D30: =IFERROR(__xludf.DUMMYFUNCTION("""COMPUTED_VALUE"""),"KOMATSU") -> KOMATSU | E30: =IFERROR(__xludf.DUMMYFUNCTION("""COMPUTED_VALUE"""),"NHẬT BẢN") -> NHẬT BẢN | F30: =IFERROR(__xludf.DUMMYFUNCTION("""COMPUTED_VALUE"""),2013) -> 2013 | G30: =IFERROR(__xludf.DUMMYFUNCTION("""COMPUTED_VALUE"""),"PC40MR-3") -> PC40MR-3 | H30: =IFERROR(__xludf.DUMMYFUNCTION("""COMPUTED_VALUE"""),"40HP") -> 40HP | I30: =IFERROR(__xludf.DUMMYFUNCTION("""COMPUTED_VALUE"""),"KMTPC203K04021031") -> KMTPC203K04021031 | J30: =IFERROR(__xludf.DUMMYFUNCTION("""COMPUTED_VALUE"""),"27440") -> 27440 | K30: =IFERROR(__xludf.DUMMYFUNCTION("""COMPUTED_VALUE"""),4) -> 4 | L30: =IFERROR(__xludf.DUMMYFUNCTION("""COMPUTED_VALUE"""),"KLH") -> KLH
A31: =IFERROR(__xludf.DUMMYFUNCTION("""COMPUTED_VALUE"""),"CHT-MĐA-078") -> CHT-MĐA-078 | B31: =IFERROR(__xludf.DUMMYFUNCTION("""COMPUTED_VALUE"""),"Máy đào KOMATSU bánh xích gàu 0.3m3") -> Máy đào KOMATSU bánh xích gàu 0.3m3 | C31: =IFERROR(__xludf.DUMMYFUNCTION("""COMPUTED_VALUE"""),"CGTC DP") -> CGTC DP | D31: =IFERROR(__xludf.DUMMYFUNCTION("""COMPUTED_VALUE"""),"KOMATSU") -> KOMATSU | E31: =IFERROR(__xludf.DUMMYFUNCTION("""COMPUTED_VALUE"""),"NHẬT BẢN") -> NHẬT BẢN | F31: =IFERROR(__xludf.DUMMYFUNCTION("""COMPUTED_VALUE"""),2015) -> 2015 | G31: =IFERROR(__xludf.DUMMYFUNCTION("""COMPUTED_VALUE"""),"PC40MR-3-AC") -> PC40MR-3-AC | H31: =IFERROR(__xludf.DUMMYFUNCTION("""COMPUTED_VALUE"""),"40HP") -> 40HP | I31: =IFERROR(__xludf.DUMMYFUNCTION("""COMPUTED_VALUE"""),"KMTPC203KFE023963") -> KMTPC203KFE023963 | J31: =IFERROR(__xludf.DUMMYFUNCTION("""COMPUTED_VALUE"""),"KACJ4722") -> KACJ4722 | K31: =IFERROR(__xludf.DUMMYFUNCTION("""COMPUTED_VALUE"""),4) -> 4 | L31: =IFERROR(__xludf.DUMMYFUNCTION("""COMPUTED_VALUE"""),"KLH") -> KLH
A32: =IFERROR(__xludf.DUMMYFUNCTION("""COMPUTED_VALUE"""),"CHT-XLU-008") -> CHT-XLU-008 | B32: =IFERROR(__xludf.DUMMYFUNCTION("""COMPUTED_VALUE"""),"Xe lu rung DYNAPAC 5 tấn") -> Xe lu rung DYNAPAC 5 tấn | C32: =IFERROR(__xludf.DUMMYFUNCTION("""COMPUTED_VALUE"""),"CGTC DP") -> CGTC DP | D32: =IFERROR(__xludf.DUMMYFUNCTION("""COMPUTED_VALUE"""),"HITACHI") -> HITACHI | E32: =IFERROR(__xludf.DUMMYFUNCTION("""COMPUTED_VALUE"""),"TRUNG QUỐC") -> TRUNG QUỐC | F32: =IFERROR(__xludf.DUMMYFUNCTION("""COMPUTED_VALUE"""),2005) -> 2005 | G32: =IFERROR(__xludf.DUMMYFUNCTION("""COMPUTED_VALUE"""),"CC150C-2") -> CC150C-2 | H32: =IFERROR(__xludf.DUMMYFUNCTION("""COMPUTED_VALUE"""),"75HP") -> 75HP | I32: =IFERROR(__xludf.DUMMYFUNCTION("""COMPUTED_VALUE"""),"HCM8U600L00010288") -> HCM8U600L00010288 | J32: =IFERROR(__xludf.DUMMYFUNCTION("""COMPUTED_VALUE"""),"3LD2-453954") -> 3LD2-453954 | K32: =IFERROR(__xludf.DUMMYFUNCTION("""COMPUTED_VALUE"""),2.6) -> 2.6 | L32: =IFERROR(__xludf.DUMMYFUNCTION("""COMPUTED_VALUE"""),"KLH") -> KLH
A33: =IFERROR(__xludf.DUMMYFUNCTION("""COMPUTED_VALUE"""),"CHT-MĐA-066") -> CHT-MĐA-066 | B33: =IFERROR(__xludf.DUMMYFUNCTION("""COMPUTED_VALUE"""),"Máy đào KOMATSU bánh lốp gàu 0.7m3") -> Máy đào KOMATSU bánh lốp gàu 0.7m3 | C33: =IFERROR(__xludf.DUMMYFUNCTION("""COMPUTED_VALUE"""),"CGTC DP") -> CGTC DP | D33: =IFERROR(__xludf.DUMMYFUNCTION("""COMPUTED_VALUE"""),"KOMATSU") -> KOMATSU | E33: =IFERROR(__xludf.DUMMYFUNCTION("""COMPUTED_VALUE"""),"ĐỨC") -> ĐỨC | F33: =IFERROR(__xludf.DUMMYFUNCTION("""COMPUTED_VALUE"""),2006) -> 2006 | G33: =IFERROR(__xludf.DUMMYFUNCTION("""COMPUTED_VALUE"""),"PW160-7") -> PW160-7 | H33: =IFERROR(__xludf.DUMMYFUNCTION("""COMPUTED_VALUE"""),"120HP") -> 120HP | I33: =IFERROR(__xludf.DUMMYFUNCTION("""COMPUTED_VALUE"""),"KMTPW013T79H50346") -> KMTPW013T79H50346 | J33: =IFERROR(__xludf.DUMMYFUNCTION("""COMPUTED_VALUE"""),"21721047") -> 21721047 | K33: =IFERROR(__xludf.DUMMYFUNCTION("""COMPUTED_VALUE"""),10) -> 10 | L33: =IFERROR(__xludf.DUMMYFUNCTION("""COMPUTED_VALUE"""),"KLH") -> KLH
A34: =IFERROR(__xludf.DUMMYFUNCTION("""COMPUTED_VALUE"""),"CHT-MĐA-067") -> CHT-MĐA-067 | B34: =IFERROR(__xludf.DUMMYFUNCTION("""COMPUTED_VALUE"""),"Máy đào KOMATSU bánh lốp gàu 0.8m3") -> Máy đào KOMATSU bánh lốp gàu 0.8m3 | C34: =IFERROR(__xludf.DUMMYFUNCTION("""COMPUTED_VALUE"""),"CGTC DP") -> CGTC DP | D34: =IFERROR(__xludf.DUMMYFUNCTION("""COMPUTED_VALUE"""),"KOMATSU") -> KOMATSU | E34: =IFERROR(__xludf.DUMMYFUNCTION("""COMPUTED_VALUE"""),"NHẬT BẢN") -> NHẬT BẢN | F34: =IFERROR(__xludf.DUMMYFUNCTION("""COMPUTED_VALUE"""),2012) -> 2012 | G34: =IFERROR(__xludf.DUMMYFUNCTION("""COMPUTED_VALUE"""),"PW200-7") -> PW200-7 | H34: =IFERROR(__xludf.DUMMYFUNCTION("""COMPUTED_VALUE"""),"150HP") -> 150HP | I34: =IFERROR(__xludf.DUMMYFUNCTION("""COMPUTED_VALUE"""),"KMTPW015K79H50237") -> KMTPW015K79H50237 | J34: =IFERROR(__xludf.DUMMYFUNCTION("""COMPUTED_VALUE"""),"21719691") -> 21719691 | K34: =IFERROR(__xludf.DUMMYFUNCTION("""COMPUTED_VALUE"""),12.5) -> 12.5 | L34: =IFERROR(__xludf.DUMMYFUNCTION("""COMPUTED_VALUE"""),"KLH") -> KLH
A35: =IFERROR(__xludf.DUMMYFUNCTION("""COMPUTED_VALUE"""),"CHT-MĐA-072") -> CHT-MĐA-072 | B35: =IFERROR(__xludf.DUMMYFUNCTION("""COMPUTED_VALUE"""),"Máy đào KOMATSU bánh xích gàu 0.8m3") -> Máy đào KOMATSU bánh xích gàu 0.8m3 | C35: =IFERROR(__xludf.DUMMYFUNCTION("""COMPUTED_VALUE"""),"CGTC DP") -> CGTC DP | D35: =IFERROR(__xludf.DUMMYFUNCTION("""COMPUTED_VALUE"""),"KOMATSU") -> KOMATSU | E35: =IFERROR(__xludf.DUMMYFUNCTION("""COMPUTED_VALUE"""),"NHẬT BẢN") -> NHẬT BẢN | F35: =IFERROR(__xludf.DUMMYFUNCTION("""COMPUTED_VALUE"""),2005) -> 2005 | G35: =IFERROR(__xludf.DUMMYFUNCTION("""COMPUTED_VALUE"""),"PC228US-3N0") -> PC228US-3N0 | H35: =IFERROR(__xludf.DUMMYFUNCTION("""COMPUTED_VALUE"""),"145HP") -> 145HP | I35: =IFERROR(__xludf.DUMMYFUNCTION("""COMPUTED_VALUE"""),"KMTPC057E02032035") -> KMTPC057E02032035 | J35: =IFERROR(__xludf.DUMMYFUNCTION("""COMPUTED_VALUE"""),"6D1022638264") -> 6D1022638264 | K35: =IFERROR(__xludf.DUMMYFUNCTION("""COMPUTED_VALUE"""),14) -> 14 | L35: =IFERROR(__xludf.DUMMYFUNCTION("""COMPUTED_VALUE"""),"KLH") -> KLH
A36: =IFERROR(__xludf.DUMMYFUNCTION("""COMPUTED_VALUE"""),"CHT-MUI-011") -> CHT-MUI-011 | B36: =IFERROR(__xludf.DUMMYFUNCTION("""COMPUTED_VALUE"""),"Máy ủi KOMATSU D31PX") -> Máy ủi KOMATSU D31PX | C36: =IFERROR(__xludf.DUMMYFUNCTION("""COMPUTED_VALUE"""),"CGTC DP") -> CGTC DP | D36: =IFERROR(__xludf.DUMMYFUNCTION("""COMPUTED_VALUE"""),"KOMATSU") -> KOMATSU | E36: =IFERROR(__xludf.DUMMYFUNCTION("""COMPUTED_VALUE"""),"NHẬT BẢN") -> NHẬT BẢN | F36: =IFERROR(__xludf.DUMMYFUNCTION("""COMPUTED_VALUE"""),2003) -> 2003 | G36: =IFERROR(__xludf.DUMMYFUNCTION("""COMPUTED_VALUE"""),"D31PX-21") -> D31PX-21 | H36: =IFERROR(__xludf.DUMMYFUNCTION("""COMPUTED_VALUE"""),"76HP") -> 76HP | I36: =IFERROR(__xludf.DUMMYFUNCTION("""COMPUTED_VALUE"""),"D31PX2150296") -> D31PX2150296 | J36: =IFERROR(__xludf.DUMMYFUNCTION("""COMPUTED_VALUE"""),"4D10226319872") -> 4D10226319872 | K36: =IFERROR(__xludf.DUMMYFUNCTION("""COMPUTED_VALUE"""),8) -> 8 | L36: =IFERROR(__xludf.DUMMYFUNCTION("""COMPUTED_VALUE"""),"KLH") -> KLH
A37: =IFERROR(__xludf.DUMMYFUNCTION("""COMPUTED_VALUE"""),"CHT-XTA-030") -> CHT-XTA-030 | B37: =IFERROR(__xludf.DUMMYFUNCTION("""COMPUTED_VALUE"""),"Xe ben FD150") -> Xe ben FD150 | C37: =IFERROR(__xludf.DUMMYFUNCTION("""COMPUTED_VALUE"""),"CGTC DP") -> CGTC DP | D37: =IFERROR(__xludf.DUMMYFUNCTION("""COMPUTED_VALUE"""),"THACO FORLAND") -> THACO FORLAND | E37: =IFERROR(__xludf.DUMMYFUNCTION("""COMPUTED_VALUE"""),"VIỆT NAM") -> VIỆT NAM | F37: =IFERROR(__xludf.DUMMYFUNCTION("""COMPUTED_VALUE"""),2024) -> 2024 | G37: =IFERROR(__xludf.DUMMYFUNCTION("""COMPUTED_VALUE"""),"FD150-4WD ") -> FD150-4WD | H37: =IFERROR(__xludf.DUMMYFUNCTION("""COMPUTED_VALUE"""),"150HP") -> 150HP | I37: =IFERROR(__xludf.DUMMYFUNCTION("""COMPUTED_VALUE"""),"RNHF16FYART000834") -> RNHF16FYART000834 | J37: =IFERROR(__xludf.DUMMYFUNCTION("""COMPUTED_VALUE"""),"D59M1N01254") -> D59M1N01254 | K37: =IFERROR(__xludf.DUMMYFUNCTION("""COMPUTED_VALUE"""),0.63) -> 0.63 | L37: =IFERROR(__xludf.DUMMYFUNCTION("""COMPUTED_VALUE"""),"KLH") -> KLH
A38: =IFERROR(__xludf.DUMMYFUNCTION("""COMPUTED_VALUE"""),"CHT-XTA-031") -> CHT-XTA-031 | B38: =IFERROR(__xludf.DUMMYFUNCTION("""COMPUTED_VALUE"""),"Xe ben FD150") -> Xe ben FD150 | C38: =IFERROR(__xludf.DUMMYFUNCTION("""COMPUTED_VALUE"""),"CGTC DP") -> CGTC DP | D38: =IFERROR(__xludf.DUMMYFUNCTION("""COMPUTED_VALUE"""),"THACO FORLAND") -> THACO FORLAND | E38: =IFERROR(__xludf.DUMMYFUNCTION("""COMPUTED_VALUE"""),"VIỆT NAM") -> VIỆT NAM | F38: =IFERROR(__xludf.DUMMYFUNCTION("""COMPUTED_VALUE"""),2024) -> 2024 | G38: =IFERROR(__xludf.DUMMYFUNCTION("""COMPUTED_VALUE"""),"FD150-4WD") -> FD150-4WD | H38: =IFERROR(__xludf.DUMMYFUNCTION("""COMPUTED_VALUE"""),"150HP") -> 150HP | I38: =IFERROR(__xludf.DUMMYFUNCTION("""COMPUTED_VALUE"""),"RNHF16FYART000835") -> RNHF16FYART000835 | J38: =IFERROR(__xludf.DUMMYFUNCTION("""COMPUTED_VALUE"""),"D59M1N01360") -> D59M1N01360 | K38: =IFERROR(__xludf.DUMMYFUNCTION("""COMPUTED_VALUE"""),0.63) -> 0.63 | L38: =IFERROR(__xludf.DUMMYFUNCTION("""COMPUTED_VALUE"""),"KLH") -> KLH
A39: =IFERROR(__xludf.DUMMYFUNCTION("""COMPUTED_VALUE"""),"CHT-XTA-037") -> CHT-XTA-037 | B39: =IFERROR(__xludf.DUMMYFUNCTION("""COMPUTED_VALUE"""),"Xe ben FC150") -> Xe ben FC150 | C39: =IFERROR(__xludf.DUMMYFUNCTION("""COMPUTED_VALUE"""),"CGTC DP") -> CGTC DP | D39: =IFERROR(__xludf.DUMMYFUNCTION("""COMPUTED_VALUE"""),"THACO FORLAND") -> THACO FORLAND | E39: =IFERROR(__xludf.DUMMYFUNCTION("""COMPUTED_VALUE"""),"VIỆT NAM") -> VIỆT NAM | F39: =IFERROR(__xludf.DUMMYFUNCTION("""COMPUTED_VALUE"""),2024) -> 2024 | G39: =IFERROR(__xludf.DUMMYFUNCTION("""COMPUTED_VALUE"""),"FC150-4WD") -> FC150-4WD | H39: =IFERROR(__xludf.DUMMYFUNCTION("""COMPUTED_VALUE"""),"150HP") -> 150HP | I39: =IFERROR(__xludf.DUMMYFUNCTION("""COMPUTED_VALUE"""),"RNHF16FYBRT000132") -> RNHF16FYBRT000132 | J39: =IFERROR(__xludf.DUMMYFUNCTION("""COMPUTED_VALUE"""),"D59M1N01088") -> D59M1N01088 | K39: =IFERROR(__xludf.DUMMYFUNCTION("""COMPUTED_VALUE"""),4.5) -> 4.5 | L39: =IFERROR(__xludf.DUMMYFUNCTION("""COMPUTED_VALUE"""),"KLH") -> KLH
A40: =IFERROR(__xludf.DUMMYFUNCTION("""COMPUTED_VALUE"""),"CHT-XTA-038") -> CHT-XTA-038 | B40: =IFERROR(__xludf.DUMMYFUNCTION("""COMPUTED_VALUE"""),"Xe ben FC150") -> Xe ben FC150 | C40: =IFERROR(__xludf.DUMMYFUNCTION("""COMPUTED_VALUE"""),"CGTC DP") -> CGTC DP | D40: =IFERROR(__xludf.DUMMYFUNCTION("""COMPUTED_VALUE"""),"THACO FORLAND") -> THACO FORLAND | E40: =IFERROR(__xludf.DUMMYFUNCTION("""COMPUTED_VALUE"""),"VIỆT NAM") -> VIỆT NAM | F40: =IFERROR(__xludf.DUMMYFUNCTION("""COMPUTED_VALUE"""),2024) -> 2024 | G40: =IFERROR(__xludf.DUMMYFUNCTION("""COMPUTED_VALUE"""),"FC150-4WD") -> FC150-4WD | H40: =IFERROR(__xludf.DUMMYFUNCTION("""COMPUTED_VALUE"""),"150HP") -> 150HP | I40: =IFERROR(__xludf.DUMMYFUNCTION("""COMPUTED_VALUE"""),"RNHF16FYBRT000133") -> RNHF16FYBRT000133 | J40: =IFERROR(__xludf.DUMMYFUNCTION("""COMPUTED_VALUE"""),"D59M1N01089") -> D59M1N01089 | K40: =IFERROR(__xludf.DUMMYFUNCTION("""COMPUTED_VALUE"""),0.63) -> 0.63 | L40: =IFERROR(__xludf.DUMMYFUNCTION("""COMPUTED_VALUE"""),"KLH") -> KLH
...

Sheet 01. TH
A2: TỔNG HỢP XE - MÁY MÓC THIẾT BỊ KLH KOUNMOM
A3: STT | B3: TÊN MÁY MÓC THIẾT BỊ | C3: Công suất | D3: Kích thước | E3: Đvt | F3: KV DAUPENH | O3: KV LUMPHAT | S3: KV ANDONGMEAS | W3: KLH | AE3: TỔNG | AF3: HƯ HỎNG | AH3: Ghi chú
F4: CGTC DP | G4: CGLĐ DP | H4: XN Chuối DP1 | I4: XN Chuối DP2 | J4: XN Chuối DP3 | K4: CAT DP | L4: Xưởng Cơ khí DP | M4: NM NHỰA -XỐP DP | N4: Tổng kho | O4: CGTC LP | P4: CGLĐ LP | Q4: XN Chuối LP1 | R4: XN Chuối LP3 | S4: CGTC AD | T4: CAT AD | U4: XN Bò AD | V4: Xưởng Cơ khí ADM&LP | W4: Phòng GNVC | X4: Trạm trộn bê tông | Y4: Ban điện nước | Z4: THACO ID&ME | AA4: HÀNH CHÍNH KLH | AB4: THAGRICONS | AC4: BAN CG-CK & SXCN | AD4: BAN KT CHUỐI
A5: 1 | B5: Máy đào | D5: =IFERROR(VLOOKUP(B5,'Danh mục'!$G:$U,15,0),"") | F5: =SUM(F6:F16) -> 17 | G5: =SUM(G6:G16) -> 0 | H5: =SUM(H6:H16) -> 0 | I5: =SUM(I6:I16) -> 0 | J5: =SUM(J6:J16) -> 0 | K5: =SUM(K6:K16) -> 0 | L5: =SUM(L6:L16) -> 0 | M5: =SUM(M6:M16) -> 0 | ... AE5: =SUM(AE6:AE16) -> 37 | AF5: 8 | AG5: =AE5+AE17+AE25+AE28+AE33+AE48+AE57+AE67+AE77+AE85+AE90+AE128+AE134+AE140+AE147+AE159+AE162+AE164+AE166+AE168+AE170+AE180+AE183+AE202+AE205+AE230+AE254+AE256 -> 403
B6: Máy đào CAT 305 bánh xích gàu 0.3m3 | C6: 45HP | D6: =IFERROR(VLOOKUP(B6,'Danh mục'!$G:$U,15,0),"") -> 5340 x 1980 x 1895 | E6: Xe | F6: =COUNTIFS('TỔNG KLH + TN'!$B:$B,'01. TH'!$B6,'TỔNG KLH + TN'!$C:$C,'01. TH'!F$4) -> 0 | G6: =COUNTIFS('TỔNG KLH + TN'!$B:$B,'01. TH'!$B6,'TỔNG KLH + TN'!$C:$C,'01. TH'!G$4) -> 0 | H6: =COUNTIFS('TỔNG KLH + TN'!$B:$B,'01. TH'!$B6,'TỔNG KLH + TN'!$C:$C,'01. TH'!H$4) -> 0 | I6: =COUNTIFS('TỔNG KLH + TN'!$B:$B,'01. TH'!$B6,'TỔNG KLH + TN'!$C:$C,'01. TH'!I$4) -> 0 | J6: =COUNTIFS('TỔNG KLH + TN'!$B:$B,'01. TH'!$B6,'TỔNG KLH + TN'!$C:$C,'01. TH'!J$4) -> 0 | K6: =COUNTIFS('TỔNG KLH + TN'!$B:$B,'01. TH'!$B6,'TỔNG KLH + TN'!$C:$C,'01. TH'!K$4) -> 0 | L6: =COUNTIFS('TỔNG KLH + TN'!$B:$B,'01. TH'!$B6,'TỔNG KLH + TN'!$C:$C,'01. TH'!L$4) -> 0 | M6: =COUNTIFS('TỔNG KLH + TN'!$B:$B,'01. TH'!$B6,'TỔNG KLH + TN'!$C:$C,'01. TH'!M$4) -> 0 | ... AD6: =COUNTIFS('TỔNG KLH + TN'!$B:$B,'01. TH'!$B6,'TỔNG KLH + TN'!$C:$C,'01. TH'!AD$4) -> 0 | AE6: =SUM(F6:AD6) -> 1 | AG6: =IF(AE6=SUM(F6:AD6),"ok","SAI") -> ok
B7: Máy đào DX140W bánh lốp gàu 0.7m3 | C7: 130HP | D7: =IFERROR(VLOOKUP(B7,'Danh mục'!$G:$U,15,0),"") -> 7235 x 2496 x 3351 | E7: Xe | F7: =COUNTIFS('TỔNG KLH + TN'!$B:$B,'01. TH'!$B7,'TỔNG KLH + TN'!$C:$C,'01. TH'!F$4) -> 2 | G7: =COUNTIFS('TỔNG KLH + TN'!$B:$B,'01. TH'!$B7,'TỔNG KLH + TN'!$C:$C,'01. TH'!G$4) -> 0 | H7: =COUNTIFS('TỔNG KLH + TN'!$B:$B,'01. TH'!$B7,'TỔNG KLH + TN'!$C:$C,'01. TH'!H$4) -> 0 | I7: =COUNTIFS('TỔNG KLH + TN'!$B:$B,'01. TH'!$B7,'TỔNG KLH + TN'!$C:$C,'01. TH'!I$4) -> 0 | J7: =COUNTIFS('TỔNG KLH + TN'!$B:$B,'01. TH'!$B7,'TỔNG KLH + TN'!$C:$C,'01. TH'!J$4) -> 0 | K7: =COUNTIFS('TỔNG KLH + TN'!$B:$B,'01. TH'!$B7,'TỔNG KLH + TN'!$C:$C,'01. TH'!K$4) -> 0 | L7: =COUNTIFS('TỔNG KLH + TN'!$B:$B,'01. TH'!$B7,'TỔNG KLH + TN'!$C:$C,'01. TH'!L$4) -> 0 | M7: =COUNTIFS('TỔNG KLH + TN'!$B:$B,'01. TH'!$B7,'TỔNG KLH + TN'!$C:$C,'01. TH'!M$4) -> 0 | ... AD7: =COUNTIFS('TỔNG KLH + TN'!$B:$B,'01. TH'!$B7,'TỔNG KLH + TN'!$C:$C,'01. TH'!AD$4) -> 0 | AE7: =SUM(F7:AD7) -> 6 | AG7: =IF(AE7=SUM(F7:AD7),"ok","SAI") -> ok
B8: Máy đào KOBELCO bánh xích gàu 1.2m3 | C8: 130HP | D8: =IFERROR(VLOOKUP(B8,'Danh mục'!$G:$U,15,0),"") -> 9560 x 2800 x 3160 | E8: Xe | F8: =COUNTIFS('TỔNG KLH + TN'!$B:$B,'01. TH'!$B8,'TỔNG KLH + TN'!$C:$C,'01. TH'!F$4) -> 1 | G8: =COUNTIFS('TỔNG KLH + TN'!$B:$B,'01. TH'!$B8,'TỔNG KLH + TN'!$C:$C,'01. TH'!G$4) -> 0 | H8: =COUNTIFS('TỔNG KLH + TN'!$B:$B,'01. TH'!$B8,'TỔNG KLH + TN'!$C:$C,'01. TH'!H$4) -> 0 | I8: =COUNTIFS('TỔNG KLH + TN'!$B:$B,'01. TH'!$B8,'TỔNG KLH + TN'!$C:$C,'01. TH'!I$4) -> 0 | J8: =COUNTIFS('TỔNG KLH + TN'!$B:$B,'01. TH'!$B8,'TỔNG KLH + TN'!$C:$C,'01. TH'!J$4) -> 0 | K8: =COUNTIFS('TỔNG KLH + TN'!$B:$B,'01. TH'!$B8,'TỔNG KLH + TN'!$C:$C,'01. TH'!K$4) -> 0 | L8: =COUNTIFS('TỔNG KLH + TN'!$B:$B,'01. TH'!$B8,'TỔNG KLH + TN'!$C:$C,'01. TH'!L$4) -> 0 | M8: =COUNTIFS('TỔNG KLH + TN'!$B:$B,'01. TH'!$B8,'TỔNG KLH + TN'!$C:$C,'01. TH'!M$4) -> 0 | ... AD8: =COUNTIFS('TỔNG KLH + TN'!$B:$B,'01. TH'!$B8,'TỔNG KLH + TN'!$C:$C,'01. TH'!AD$4) -> 0 | AE8: =SUM(F8:AD8) -> 1 | AG8: =IF(AE8=SUM(F8:AD8),"ok","SAI") -> ok
B9: Máy đào KOMATSU bánh lốp gàu 0.7m3 | C9: 130HP | D9: =IFERROR(VLOOKUP(B9,'Danh mục'!$G:$U,15,0),"") -> 8358 x 2540 x 3200 | E9: Xe | F9: =COUNTIFS('TỔNG KLH + TN'!$B:$B,'01. TH'!$B9,'TỔNG KLH + TN'!$C:$C,'01. TH'!F$4) -> 1 | G9: =COUNTIFS('TỔNG KLH + TN'!$B:$B,'01. TH'!$B9,'TỔNG KLH + TN'!$C:$C,'01. TH'!G$4) -> 0 | H9: =COUNTIFS('TỔNG KLH + TN'!$B:$B,'01. TH'!$B9,'TỔNG KLH + TN'!$C:$C,'01. TH'!H$4) -> 0 | I9: =COUNTIFS('TỔNG KLH + TN'!$B:$B,'01. TH'!$B9,'TỔNG KLH + TN'!$C:$C,'01. TH'!I$4) -> 0 | J9: =COUNTIFS('TỔNG KLH + TN'!$B:$B,'01. TH'!$B9,'TỔNG KLH + TN'!$C:$C,'01. TH'!J$4) -> 0 | K9: =COUNTIFS('TỔNG KLH + TN'!$B:$B,'01. TH'!$B9,'TỔNG KLH + TN'!$C:$C,'01. TH'!K$4) -> 0 | L9: =COUNTIFS('TỔNG KLH + TN'!$B:$B,'01. TH'!$B9,'TỔNG KLH + TN'!$C:$C,'01. TH'!L$4) -> 0 | M9: =COUNTIFS('TỔNG KLH + TN'!$B:$B,'01. TH'!$B9,'TỔNG KLH + TN'!$C:$C,'01. TH'!M$4) -> 0 | ... AD9: =COUNTIFS('TỔNG KLH + TN'!$B:$B,'01. TH'!$B9,'TỔNG KLH + TN'!$C:$C,'01. TH'!AD$4) -> 0 | AE9: =SUM(F9:AD9) -> 1 | AG9: =IF(AE9=SUM(F9:AD9),"ok","SAI") -> ok
B10: Máy đào KOMATSU bánh lốp gàu 0.8m3 | C10: 150HP | D10: =IFERROR(VLOOKUP(B10,'Danh mục'!$G:$U,15,0),"") -> 9660 x 2550 x 3985 | E10: Xe | F10: =COUNTIFS('TỔNG KLH + TN'!$B:$B,'01. TH'!$B10,'TỔNG KLH + TN'!$C:$C,'01. TH'!F$4) -> 1 | G10: =COUNTIFS('TỔNG KLH + TN'!$B:$B,'01. TH'!$B10,'TỔNG KLH + TN'!$C:$C,'01. TH'!G$4) -> 0 | H10: =COUNTIFS('TỔNG KLH + TN'!$B:$B,'01. TH'!$B10,'TỔNG KLH + TN'!$C:$C,'01. TH'!H$4) -> 0 | I10: =COUNTIFS('TỔNG KLH + TN'!$B:$B,'01. TH'!$B10,'TỔNG KLH + TN'!$C:$C,'01. TH'!I$4) -> 0 | J10: =COUNTIFS('TỔNG KLH + TN'!$B:$B,'01. TH'!$B10,'TỔNG KLH + TN'!$C:$C,'01. TH'!J$4) -> 0 | K10: =COUNTIFS('TỔNG KLH + TN'!$B:$B,'01. TH'!$B10,'TỔNG KLH + TN'!$C:$C,'01. TH'!K$4) -> 0 | L10: =COUNTIFS('TỔNG KLH + TN'!$B:$B,'01. TH'!$B10,'TỔNG KLH + TN'!$C:$C,'01. TH'!L$4) -> 0 | M10: =COUNTIFS('TỔNG KLH + TN'!$B:$B,'01. TH'!$B10,'TỔNG KLH + TN'!$C:$C,'01. TH'!M$4) -> 0 | ... AD10: =COUNTIFS('TỔNG KLH + TN'!$B:$B,'01. TH'!$B10,'TỔNG KLH + TN'!$C:$C,'01. TH'!AD$4) -> 0 | AE10: =SUM(F10:AD10) -> 1 | AG10: =IF(AE10=SUM(F10:AD10),"ok","SAI") -> ok
B11: Máy đào KOMATSU bánh xích gàu 0.3m3 | C11: 45HP | D11: =IFERROR(VLOOKUP(B11,'Danh mục'!$G:$U,15,0),"") -> 5260 x 1760 x 2415 | E11: Xe | F11: =COUNTIFS('TỔNG KLH + TN'!$B:$B,'01. TH'!$B11,'TỔNG KLH + TN'!$C:$C,'01. TH'!F$4) -> 8 | G11: =COUNTIFS('TỔNG KLH + TN'!$B:$B,'01. TH'!$B11,'TỔNG KLH + TN'!$C:$C,'01. TH'!G$4) -> 0 | H11: =COUNTIFS('TỔNG KLH + TN'!$B:$B,'01. TH'!$B11,'TỔNG KLH + TN'!$C:$C,'01. TH'!H$4) -> 0 | I11: =COUNTIFS('TỔNG KLH + TN'!$B:$B,'01. TH'!$B11,'TỔNG KLH + TN'!$C:$C,'01. TH'!I$4) -> 0 | J11: =COUNTIFS('TỔNG KLH + TN'!$B:$B,'01. TH'!$B11,'TỔNG KLH + TN'!$C:$C,'01. TH'!J$4) -> 0 | K11: =COUNTIFS('TỔNG KLH + TN'!$B:$B,'01. TH'!$B11,'TỔNG KLH + TN'!$C:$C,'01. TH'!K$4) -> 0 | L11: =COUNTIFS('TỔNG KLH + TN'!$B:$B,'01. TH'!$B11,'TỔNG KLH + TN'!$C:$C,'01. TH'!L$4) -> 0 | M11: =COUNTIFS('TỔNG KLH + TN'!$B:$B,'01. TH'!$B11,'TỔNG KLH + TN'!$C:$C,'01. TH'!M$4) -> 0 | ... AD11: =COUNTIFS('TỔNG KLH + TN'!$B:$B,'01. TH'!$B11,'TỔNG KLH + TN'!$C:$C,'01. TH'!AD$4) -> 0 | AE11: =SUM(F11:AD11) -> 12 | AG11: =IF(AE11=SUM(F11:AD11),"ok","SAI") -> ok
B12: Máy đào KOMATSU bánh xích gàu 0.8m3 | C12: 150HP | D12: =IFERROR(VLOOKUP(B12,'Danh mục'!$G:$U,15,0),"") -> 8700 x 2800 x 3010 | E12: Xe | F12: =COUNTIFS('TỔNG KLH + TN'!$B:$B,'01. TH'!$B12,'TỔNG KLH + TN'!$C:$C,'01. TH'!F$4) -> 1 | G12: =COUNTIFS('TỔNG KLH + TN'!$B:$B,'01. TH'!$B12,'TỔNG KLH + TN'!$C:$C,'01. TH'!G$4) -> 0 | H12: =COUNTIFS('TỔNG KLH + TN'!$B:$B,'01. TH'!$B12,'TỔNG KLH + TN'!$C:$C,'01. TH'!H$4) -> 0 | I12: =COUNTIFS('TỔNG KLH + TN'!$B:$B,'01. TH'!$B12,'TỔNG KLH + TN'!$C:$C,'01. TH'!I$4) -> 0 | J12: =COUNTIFS('TỔNG KLH + TN'!$B:$B,'01. TH'!$B12,'TỔNG KLH + TN'!$C:$C,'01. TH'!J$4) -> 0 | K12: =COUNTIFS('TỔNG KLH + TN'!$B:$B,'01. TH'!$B12,'TỔNG KLH + TN'!$C:$C,'01. TH'!K$4) -> 0 | L12: =COUNTIFS('TỔNG KLH + TN'!$B:$B,'01. TH'!$B12,'TỔNG KLH + TN'!$C:$C,'01. TH'!L$4) -> 0 | M12: =COUNTIFS('TỔNG KLH + TN'!$B:$B,'01. TH'!$B12,'TỔNG KLH + TN'!$C:$C,'01. TH'!M$4) -> 0 | ... AD12: =COUNTIFS('TỔNG KLH + TN'!$B:$B,'01. TH'!$B12,'TỔNG KLH + TN'!$C:$C,'01. TH'!AD$4) -> 0 | AE12: =SUM(F12:AD12) -> 4 | AG12: =IF(AE12=SUM(F12:AD12),"ok","SAI") -> ok
B13: Máy đào ROBEX 140W bánh lốp gàu 0.5m3 | C13: 130HP | D13: =IFERROR(VLOOKUP(B13,'Danh mục'!$G:$U,15,0),"") -> 7820 x 2500 x 3140 | E13: Xe | F13: =COUNTIFS('TỔNG KLH + TN'!$B:$B,'01. TH'!$B13,'TỔNG KLH + TN'!$C:$C,'01. TH'!F$4) -> 0 | G13: =COUNTIFS('TỔNG KLH + TN'!$B:$B,'01. TH'!$B13,'TỔNG KLH + TN'!$C:$C,'01. TH'!G$4) -> 0 | H13: =COUNTIFS('TỔNG KLH + TN'!$B:$B,'01. TH'!$B13,'TỔNG KLH + TN'!$C:$C,'01. TH'!H$4) -> 0 | I13: =COUNTIFS('TỔNG KLH + TN'!$B:$B,'01. TH'!$B13,'TỔNG KLH + TN'!$C:$C,'01. TH'!I$4) -> 0 | J13: =COUNTIFS('TỔNG KLH + TN'!$B:$B,'01. TH'!$B13,'TỔNG KLH + TN'!$C:$C,'01. TH'!J$4) -> 0 | K13: =COUNTIFS('TỔNG KLH + TN'!$B:$B,'01. TH'!$B13,'TỔNG KLH + TN'!$C:$C,'01. TH'!K$4) -> 0 | L13: =COUNTIFS('TỔNG KLH + TN'!$B:$B,'01. TH'!$B13,'TỔNG KLH + TN'!$C:$C,'01. TH'!L$4) -> 0 | M13: =COUNTIFS('TỔNG KLH + TN'!$B:$B,'01. TH'!$B13,'TỔNG KLH + TN'!$C:$C,'01. TH'!M$4) -> 0 | ... AD13: =COUNTIFS('TỔNG KLH + TN'!$B:$B,'01. TH'!$B13,'TỔNG KLH + TN'!$C:$C,'01. TH'!AD$4) -> 0 | AE13: =SUM(F13:AD13) -> 0 | AG13: =IF(AE13=SUM(F13:AD13),"ok","SAI") -> ok
B14: Máy đào SH130 bánh xích gàu 0.5m3 | C14: 130HP | D14: =IFERROR(VLOOKUP(B14,'Danh mục'!$G:$U,15,0),"") -> 7640 x 2590 x 2820 | E14: Xe | F14: =COUNTIFS('TỔNG KLH + TN'!$B:$B,'01. TH'!$B14,'TỔNG KLH + TN'!$C:$C,'01. TH'!F$4) -> 1 | G14: =COUNTIFS('TỔNG KLH + TN'!$B:$B,'01. TH'!$B14,'TỔNG KLH + TN'!$C:$C,'01. TH'!G$4) -> 0 | H14: =COUNTIFS('TỔNG KLH + TN'!$B:$B,'01. TH'!$B14,'TỔNG KLH + TN'!$C:$C,'01. TH'!H$4) -> 0 | I14: =COUNTIFS('TỔNG KLH + TN'!$B:$B,'01. TH'!$B14,'TỔNG KLH + TN'!$C:$C,'01. TH'!I$4) -> 0 | J14: =COUNTIFS('TỔNG KLH + TN'!$B:$B,'01. TH'!$B14,'TỔNG KLH + TN'!$C:$C,'01. TH'!J$4) -> 0 | K14: =COUNTIFS('TỔNG KLH + TN'!$B:$B,'01. TH'!$B14,'TỔNG KLH + TN'!$C:$C,'01. TH'!K$4) -> 0 | L14: =COUNTIFS('TỔNG KLH + TN'!$B:$B,'01. TH'!$B14,'TỔNG KLH + TN'!$C:$C,'01. TH'!L$4) -> 0 | M14: =COUNTIFS('TỔNG KLH + TN'!$B:$B,'01. TH'!$B14,'TỔNG KLH + TN'!$C:$C,'01. TH'!M$4) -> 0 | ... AD14: =COUNTIFS('TỔNG KLH + TN'!$B:$B,'01. TH'!$B14,'TỔNG KLH + TN'!$C:$C,'01. TH'!AD$4) -> 0 | AE14: =SUM(F14:AD14) -> 2 | AG14: =IF(AE14=SUM(F14:AD14),"ok","SAI") -> ok
B15: Máy đào SH210 bánh xích gàu 0.9m3 | C15: 160HP | D15: =IFERROR(VLOOKUP(B15,'Danh mục'!$G:$U,15,0),"") -> 9460 x 2800 x 3200 | E15: Xe | F15: =COUNTIFS('TỔNG KLH + TN'!$B:$B,'01. TH'!$B15,'TỔNG KLH + TN'!$C:$C,'01. TH'!F$4) -> 2 | G15: =COUNTIFS('TỔNG KLH + TN'!$B:$B,'01. TH'!$B15,'TỔNG KLH + TN'!$C:$C,'01. TH'!G$4) -> 0 | H15: =COUNTIFS('TỔNG KLH + TN'!$B:$B,'01. TH'!$B15,'TỔNG KLH + TN'!$C:$C,'01. TH'!H$4) -> 0 | I15: =COUNTIFS('TỔNG KLH + TN'!$B:$B,'01. TH'!$B15,'TỔNG KLH + TN'!$C:$C,'01. TH'!I$4) -> 0 | J15: =COUNTIFS('TỔNG KLH + TN'!$B:$B,'01. TH'!$B15,'TỔNG KLH + TN'!$C:$C,'01. TH'!J$4) -> 0 | K15: =COUNTIFS('TỔNG KLH + TN'!$B:$B,'01. TH'!$B15,'TỔNG KLH + TN'!$C:$C,'01. TH'!K$4) -> 0 | L15: =COUNTIFS('TỔNG KLH + TN'!$B:$B,'01. TH'!$B15,'TỔNG KLH + TN'!$C:$C,'01. TH'!L$4) -> 0 | M15: =COUNTIFS('TỔNG KLH + TN'!$B:$B,'01. TH'!$B15,'TỔNG KLH + TN'!$C:$C,'01. TH'!M$4) -> 0 | ... AD15: =COUNTIFS('TỔNG KLH + TN'!$B:$B,'01. TH'!$B15,'TỔNG KLH + TN'!$C:$C,'01. TH'!AD$4) -> 0 | AE15: =SUM(F15:AD15) -> 5 | AG15: =IF(AE15=SUM(F15:AD15),"ok","SAI") -> ok
B16: Máy đào U35 bánh xích gàu 0.3m3 | C16: 45HP | D16: =IFERROR(VLOOKUP(B16,'Danh mục'!$G:$U,15,0),"") -> 4749 x 1700 x 2470 | E16: Xe | F16: =COUNTIFS('TỔNG KLH + TN'!$B:$B,'01. TH'!$B16,'TỔNG KLH + TN'!$C:$C,'01. TH'!F$4) -> 0 | G16: =COUNTIFS('TỔNG KLH + TN'!$B:$B,'01. TH'!$B16,'TỔNG KLH + TN'!$C:$C,'01. TH'!G$4) -> 0 | H16: =COUNTIFS('TỔNG KLH + TN'!$B:$B,'01. TH'!$B16,'TỔNG KLH + TN'!$C:$C,'01. TH'!H$4) -> 0 | I16: =COUNTIFS('TỔNG KLH + TN'!$B:$B,'01. TH'!$B16,'TỔNG KLH + TN'!$C:$C,'01. TH'!I$4) -> 0 | J16: =COUNTIFS('TỔNG KLH + TN'!$B:$B,'01. TH'!$B16,'TỔNG KLH + TN'!$C:$C,'01. TH'!J$4) -> 0 | K16: =COUNTIFS('TỔNG KLH + TN'!$B:$B,'01. TH'!$B16,'TỔNG KLH + TN'!$C:$C,'01. TH'!K$4) -> 0 | L16: =COUNTIFS('TỔNG KLH + TN'!$B:$B,'01. TH'!$B16,'TỔNG KLH + TN'!$C:$C,'01. TH'!L$4) -> 0 | M16: =COUNTIFS('TỔNG KLH + TN'!$B:$B,'01. TH'!$B16,'TỔNG KLH + TN'!$C:$C,'01. TH'!M$4) -> 0 | ... AD16: =COUNTIFS('TỔNG KLH + TN'!$B:$B,'01. TH'!$B16,'TỔNG KLH + TN'!$C:$C,'01. TH'!AD$4) -> 0 | AE16: =SUM(F16:AD16) -> 4 | AG16: =IF(AE16=SUM(F16:AD16),"ok","SAI") -> ok
A17: 2 | B17: Máy ủi | D17: =IFERROR(VLOOKUP(B17,'Danh mục'!$G:$U,15,0),"") | F17: =SUM(F18:F24) -> 5 | G17: =SUM(G18:G24) -> 0 | H17: =SUM(H18:H24) -> 0 | I17: =SUM(I18:I24) -> 0 | J17: =SUM(J18:J24) -> 0 | K17: =SUM(K18:K24) -> 0 | L17: =SUM(L18:L24) -> 0 | M17: =SUM(M18:M24) -> 0 | ... AE17: =SUM(AE18:AE24) -> 15 | AF17: 5 | AG17: =IF(AE17=SUM(F17:AD17),"ok","SAI") -> ok
B18: Máy ủi KOMATSU D31PX | C18: 75HP | D18: =IFERROR(VLOOKUP(B18,'Danh mục'!$G:$U,15,0),"") -> 4200 x 2980 x 2720 | E18: Xe | F18: =COUNTIFS('TỔNG KLH + TN'!$B:$B,'01. TH'!$B18,'TỔNG KLH + TN'!$C:$C,'01. TH'!F$4) -> 2 | G18: =COUNTIFS('TỔNG KLH + TN'!$B:$B,'01. TH'!$B18,'TỔNG KLH + TN'!$C:$C,'01. TH'!G$4) -> 0 | H18: =COUNTIFS('TỔNG KLH + TN'!$B:$B,'01. TH'!$B18,'TỔNG KLH + TN'!$C:$C,'01. TH'!H$4) -> 0 | I18: =COUNTIFS('TỔNG KLH + TN'!$B:$B,'01. TH'!$B18,'TỔNG KLH + TN'!$C:$C,'01. TH'!I$4) -> 0 | J18: =COUNTIFS('TỔNG KLH + TN'!$B:$B,'01. TH'!$B18,'TỔNG KLH + TN'!$C:$C,'01. TH'!J$4) -> 0 | K18: =COUNTIFS('TỔNG KLH + TN'!$B:$B,'01. TH'!$B18,'TỔNG KLH + TN'!$C:$C,'01. TH'!K$4) -> 0 | L18: =COUNTIFS('TỔNG KLH + TN'!$B:$B,'01. TH'!$B18,'TỔNG KLH + TN'!$C:$C,'01. TH'!L$4) -> 0 | M18: =COUNTIFS('TỔNG KLH + TN'!$B:$B,'01. TH'!$B18,'TỔNG KLH + TN'!$C:$C,'01. TH'!M$4) -> 0 | ... AD18: =COUNTIFS('TỔNG KLH + TN'!$B:$B,'01. TH'!$B18,'TỔNG KLH + TN'!$C:$C,'01. TH'!AD$4) -> 0 | AE18: =SUM(F18:AD18) -> 8 | AG18: =IF(AE18=SUM(F18:AD18),"ok","SAI") -> ok
B19: Máy ủi KOMATSU D31PX-21 | C19: 75HP | D19: =IFERROR(VLOOKUP(B19,'Danh mục'!$G:$U,15,0),"") -> 4200 x 2980 x 2720 | E19: Xe | F19: =COUNTIFS('TỔNG KLH + TN'!$B:$B,'01. TH'!$B19,'TỔNG KLH + TN'!$C:$C,'01. TH'!F$4) -> 0 | G19: =COUNTIFS('TỔNG KLH + TN'!$B:$B,'01. TH'!$B19,'TỔNG KLH + TN'!$C:$C,'01. TH'!G$4) -> 0 | H19: =COUNTIFS('TỔNG KLH + TN'!$B:$B,'01. TH'!$B19,'TỔNG KLH + TN'!$C:$C,'01. TH'!H$4) -> 0 | I19: =COUNTIFS('TỔNG KLH + TN'!$B:$B,'01. TH'!$B19,'TỔNG KLH + TN'!$C:$C,'01. TH'!I$4) -> 0 | J19: =COUNTIFS('TỔNG KLH + TN'!$B:$B,'01. TH'!$B19,'TỔNG KLH + TN'!$C:$C,'01. TH'!J$4) -> 0 | K19: =COUNTIFS('TỔNG KLH + TN'!$B:$B,'01. TH'!$B19,'TỔNG KLH + TN'!$C:$C,'01. TH'!K$4) -> 0 | L19: =COUNTIFS('TỔNG KLH + TN'!$B:$B,'01. TH'!$B19,'TỔNG KLH + TN'!$C:$C,'01. TH'!L$4) -> 0 | M19: =COUNTIFS('TỔNG KLH + TN'!$B:$B,'01. TH'!$B19,'TỔNG KLH + TN'!$C:$C,'01. TH'!M$4) -> 0 | ... AD19: =COUNTIFS('TỔNG KLH + TN'!$B:$B,'01. TH'!$B19,'TỔNG KLH + TN'!$C:$C,'01. TH'!AD$4) -> 0 | AE19: =SUM(F19:AD19) -> 1 | AG19: =IF(AE19=SUM(F19:AD19),"ok","SAI") -> ok
B20: Máy ủi KOMATSU D60P | C20: 190HP | D20: =IFERROR(VLOOKUP(B20,'Danh mục'!$G:$U,15,0),"") -> 5585 x 3000 x 3055 | E20: Xe | F20: =COUNTIFS('TỔNG KLH + TN'!$B:$B,'01. TH'!$B20,'TỔNG KLH + TN'!$C:$C,'01. TH'!F$4) -> 0 | G20: =COUNTIFS('TỔNG KLH + TN'!$B:$B,'01. TH'!$B20,'TỔNG KLH + TN'!$C:$C,'01. TH'!G$4) -> 0 | H20: =COUNTIFS('TỔNG KLH + TN'!$B:$B,'01. TH'!$B20,'TỔNG KLH + TN'!$C:$C,'01. TH'!H$4) -> 0 | I20: =COUNTIFS('TỔNG KLH + TN'!$B:$B,'01. TH'!$B20,'TỔNG KLH + TN'!$C:$C,'01. TH'!I$4) -> 0 | J20: =COUNTIFS('TỔNG KLH + TN'!$B:$B,'01. TH'!$B20,'TỔNG KLH + TN'!$C:$C,'01. TH'!J$4) -> 0 | K20: =COUNTIFS('TỔNG KLH + TN'!$B:$B,'01. TH'!$B20,'TỔNG KLH + TN'!$C:$C,'01. TH'!K$4) -> 0 | L20: =COUNTIFS('TỔNG KLH + TN'!$B:$B,'01. TH'!$B20,'TỔNG KLH + TN'!$C:$C,'01. TH'!L$4) -> 0 | M20: =COUNTIFS('TỔNG KLH + TN'!$B:$B,'01. TH'!$B20,'TỔNG KLH + TN'!$C:$C,'01. TH'!M$4) -> 0 | ... AD20: =COUNTIFS('TỔNG KLH + TN'!$B:$B,'01. TH'!$B20,'TỔNG KLH + TN'!$C:$C,'01. TH'!AD$4) -> 0 | AE20: =SUM(F20:AD20) -> 1 | AG20: =IF(AE20=SUM(F20:AD20),"ok","SAI") -> ok
B21: Máy ủi KOMATSU D60P-12E | C21: 190HP | D21: =IFERROR(VLOOKUP(B21,'Danh mục'!$G:$U,15,0),"") -> 5585 x 3000 x 3055 | E21: Xe | F21: =COUNTIFS('TỔNG KLH + TN'!$B:$B,'01. TH'!$B21,'TỔNG KLH + TN'!$C:$C,'01. TH'!F$4) -> 2 | G21: =COUNTIFS('TỔNG KLH + TN'!$B:$B,'01. TH'!$B21,'TỔNG KLH + TN'!$C:$C,'01. TH'!G$4) -> 0 | H21: =COUNTIFS('TỔNG KLH + TN'!$B:$B,'01. TH'!$B21,'TỔNG KLH + TN'!$C:$C,'01. TH'!H$4) -> 0 | I21: =COUNTIFS('TỔNG KLH + TN'!$B:$B,'01. TH'!$B21,'TỔNG KLH + TN'!$C:$C,'01. TH'!I$4) -> 0 | J21: =COUNTIFS('TỔNG KLH + TN'!$B:$B,'01. TH'!$B21,'TỔNG KLH + TN'!$C:$C,'01. TH'!J$4) -> 0 | K21: =COUNTIFS('TỔNG KLH + TN'!$B:$B,'01. TH'!$B21,'TỔNG KLH + TN'!$C:$C,'01. TH'!K$4) -> 0 | L21: =COUNTIFS('TỔNG KLH + TN'!$B:$B,'01. TH'!$B21,'TỔNG KLH + TN'!$C:$C,'01. TH'!L$4) -> 0 | M21: =COUNTIFS('TỔNG KLH + TN'!$B:$B,'01. TH'!$B21,'TỔNG KLH + TN'!$C:$C,'01. TH'!M$4) -> 0 | ... AD21: =COUNTIFS('TỔNG KLH + TN'!$B:$B,'01. TH'!$B21,'TỔNG KLH + TN'!$C:$C,'01. TH'!AD$4) -> 0 | AE21: =SUM(F21:AD21) -> 2 | AG21: =IF(AE21=SUM(F21:AD21),"ok","SAI") -> ok
B22: Máy ủi KOMATSU D61 | C22: 155HP | D22: =IFERROR(VLOOKUP(B22,'Danh mục'!$G:$U,15,0),"") -> 5540 x 3860 x 3150 | E22: Xe | F22: =COUNTIFS('TỔNG KLH + TN'!$B:$B,'01. TH'!$B22,'TỔNG KLH + TN'!$C:$C,'01. TH'!F$4) -> 0 | G22: =COUNTIFS('TỔNG KLH + TN'!$B:$B,'01. TH'!$B22,'TỔNG KLH + TN'!$C:$C,'01. TH'!G$4) -> 0 | H22: =COUNTIFS('TỔNG KLH + TN'!$B:$B,'01. TH'!$B22,'TỔNG KLH + TN'!$C:$C,'01. TH'!H$4) -> 0 | I22: =COUNTIFS('TỔNG KLH + TN'!$B:$B,'01. TH'!$B22,'TỔNG KLH + TN'!$C:$C,'01. TH'!I$4) -> 0 | J22: =COUNTIFS('TỔNG KLH + TN'!$B:$B,'01. TH'!$B22,'TỔNG KLH + TN'!$C:$C,'01. TH'!J$4) -> 0 | K22: =COUNTIFS('TỔNG KLH + TN'!$B:$B,'01. TH'!$B22,'TỔNG KLH + TN'!$C:$C,'01. TH'!K$4) -> 0 | L22: =COUNTIFS('TỔNG KLH + TN'!$B:$B,'01. TH'!$B22,'TỔNG KLH + TN'!$C:$C,'01. TH'!L$4) -> 0 | M22: =COUNTIFS('TỔNG KLH + TN'!$B:$B,'01. TH'!$B22,'TỔNG KLH + TN'!$C:$C,'01. TH'!M$4) -> 0 | ... AD22: =COUNTIFS('TỔNG KLH + TN'!$B:$B,'01. TH'!$B22,'TỔNG KLH + TN'!$C:$C,'01. TH'!AD$4) -> 0 | AE22: =SUM(F22:AD22) -> 1 | AG22: =IF(AE22=SUM(F22:AD22),"ok","SAI") -> ok
B23: Máy ủi KOMATSU D65P-12 | C23: 190HP | D23: =IFERROR(VLOOKUP(B23,'Danh mục'!$G:$U,15,0),"") -> 5550 x 3970 x 3090 | E23: Xe | F23: =COUNTIFS('TỔNG KLH + TN'!$B:$B,'01. TH'!$B23,'TỔNG KLH + TN'!$C:$C,'01. TH'!F$4) -> 1 | G23: =COUNTIFS('TỔNG KLH + TN'!$B:$B,'01. TH'!$B23,'TỔNG KLH + TN'!$C:$C,'01. TH'!G$4) -> 0 | H23: =COUNTIFS('TỔNG KLH + TN'!$B:$B,'01. TH'!$B23,'TỔNG KLH + TN'!$C:$C,'01. TH'!H$4) -> 0 | I23: =COUNTIFS('TỔNG KLH + TN'!$B:$B,'01. TH'!$B23,'TỔNG KLH + TN'!$C:$C,'01. TH'!I$4) -> 0 | J23: =COUNTIFS('TỔNG KLH + TN'!$B:$B,'01. TH'!$B23,'TỔNG KLH + TN'!$C:$C,'01. TH'!J$4) -> 0 | K23: =COUNTIFS('TỔNG KLH + TN'!$B:$B,'01. TH'!$B23,'TỔNG KLH + TN'!$C:$C,'01. TH'!K$4) -> 0 | L23: =COUNTIFS('TỔNG KLH + TN'!$B:$B,'01. TH'!$B23,'TỔNG KLH + TN'!$C:$C,'01. TH'!L$4) -> 0 | M23: =COUNTIFS('TỔNG KLH + TN'!$B:$B,'01. TH'!$B23,'TỔNG KLH + TN'!$C:$C,'01. TH'!M$4) -> 0 | ... AD23: =COUNTIFS('TỔNG KLH + TN'!$B:$B,'01. TH'!$B23,'TỔNG KLH + TN'!$C:$C,'01. TH'!AD$4) -> 0 | AE23: =SUM(F23:AD23) -> 1 | AG23: =IF(AE23=SUM(F23:AD23),"ok","SAI") -> ok
